2025-07-03 01:19:28,145 INFO    MainThread:54956 [wandb_setup.py:_flush():81] Current SDK version is 0.20.0
2025-07-03 01:19:28,145 INFO    MainThread:54956 [wandb_setup.py:_flush():81] Configure stats pid to 54956
2025-07-03 01:19:28,145 INFO    MainThread:54956 [wandb_setup.py:_flush():81] Loading settings from /Users/nbhsbgnb/.config/wandb/settings
2025-07-03 01:19:28,146 INFO    MainThread:54956 [wandb_setup.py:_flush():81] Loading settings from /Users/nbhsbgnb/PycharmProjects/PythonProject/PowerPINN/wandb/settings
2025-07-03 01:19:28,146 INFO    MainThread:54956 [wandb_setup.py:_flush():81] Loading settings from environment variables
2025-07-03 01:19:28,146 INFO    MainThread:54956 [wandb_init.py:setup_run_log_directory():703] Logging user logs to /Users/nbhsbgnb/PycharmProjects/PythonProject/PowerPINN/wandb/run-20250703_011928-z19lzbhw/logs/debug.log
2025-07-03 01:19:28,146 INFO    MainThread:54956 [wandb_init.py:setup_run_log_directory():704] Logging internal logs to /Users/nbhsbgnb/PycharmProjects/PythonProject/PowerPINN/wandb/run-20250703_011928-z19lzbhw/logs/debug-internal.log
2025-07-03 01:19:28,146 INFO    MainThread:54956 [wandb_init.py:init():831] calling init triggers
2025-07-03 01:19:28,146 INFO    MainThread:54956 [wandb_init.py:init():836] wandb.init called with sweep_config: {}
config: {'_wandb': {}}
2025-07-03 01:19:28,146 INFO    MainThread:54956 [wandb_init.py:init():872] starting backend
2025-07-03 01:19:28,369 INFO    MainThread:54956 [wandb_init.py:init():875] sending inform_init request
2025-07-03 01:19:28,392 INFO    MainThread:54956 [wandb_init.py:init():883] backend started and connected
2025-07-03 01:19:28,395 INFO    MainThread:54956 [wandb_init.py:init():956] updated telemetry
2025-07-03 01:19:28,415 INFO    MainThread:54956 [wandb_init.py:init():980] communicating run to backend with 90.0 second timeout
2025-07-03 01:19:28,431 WARNING MainThread:54956 [wandb_init.py:init():1613] [no run ID] interrupted
Traceback (most recent call last):
  File "/opt/anaconda3/envs/myenv/lib/python3.11/site-packages/wandb/sdk/wandb_init.py", line 1609, in init
    return wi.init(run_settings, run_config, run_printer)
           ^^^^^^^^^^^^^^^^^^^^^^^^^^^^^^^^^^^^^^^^^^^^^^
  File "/opt/anaconda3/envs/myenv/lib/python3.11/site-packages/wandb/sdk/wandb_init.py", line 999, in init
    result = wait_with_progress(
             ^^^^^^^^^^^^^^^^^^^
  File "/opt/anaconda3/envs/myenv/lib/python3.11/site-packages/wandb/sdk/mailbox/wait_with_progress.py", line 24, in wait_with_progress
    return wait_all_with_progress(
           ^^^^^^^^^^^^^^^^^^^^^^^
  File "/opt/anaconda3/envs/myenv/lib/python3.11/site-packages/wandb/sdk/mailbox/wait_with_progress.py", line 70, in wait_all_with_progress
    return _wait_handles(handle_list, timeout=progress_after)
           ^^^^^^^^^^^^^^^^^^^^^^^^^^^^^^^^^^^^^^^^^^^^^^^^^^
  File "/opt/anaconda3/envs/myenv/lib/python3.11/site-packages/wandb/sdk/mailbox/wait_with_progress.py", line 110, in _wait_handles
    results.append(handle.wait_or(timeout=remaining_timeout))
                   ^^^^^^^^^^^^^^^^^^^^^^^^^^^^^^^^^^^^^^^^^
  File "/opt/anaconda3/envs/myenv/lib/python3.11/site-packages/wandb/sdk/mailbox/mailbox_handle.py", line 118, in wait_or
    return self._fn(self._handle.wait_or(timeout=timeout))
                    ^^^^^^^^^^^^^^^^^^^^^^^^^^^^^^^^^^^^^
  File "/opt/anaconda3/envs/myenv/lib/python3.11/site-packages/wandb/sdk/mailbox/response_handle.py", line 84, in wait_or
    if not self._event.wait(timeout=timeout):
           ^^^^^^^^^^^^^^^^^^^^^^^^^^^^^^^^^
  File "/opt/anaconda3/envs/myenv/lib/python3.11/threading.py", line 629, in wait
    signaled = self._cond.wait(timeout)
               ^^^^^^^^^^^^^^^^^^^^^^^^
  File "/opt/anaconda3/envs/myenv/lib/python3.11/threading.py", line 331, in wait
    gotit = waiter.acquire(True, timeout)
            ^^^^^^^^^^^^^^^^^^^^^^^^^^^^^
KeyboardInterrupt
2025-07-03 01:19:28,433 WARNING MsgRouterThr:54956 [router.py:message_loop():63] [no run ID] message_loop has been closed
Traceback (most recent call last):
  File "/opt/anaconda3/envs/myenv/lib/python3.11/site-packages/wandb/sdk/interface/router_sock.py", line 27, in _read_message
    return self._sock_client.read_server_response(timeout=1)
           ^^^^^^^^^^^^^^^^^^^^^^^^^^^^^^^^^^^^^^^^^^^^^^^^^
  File "/opt/anaconda3/envs/myenv/lib/python3.11/site-packages/wandb/sdk/lib/sock_client.py", line 235, in read_server_response
    data = self._read_packet_bytes(timeout=timeout)
           ^^^^^^^^^^^^^^^^^^^^^^^^^^^^^^^^^^^^^^^^
  File "/opt/anaconda3/envs/myenv/lib/python3.11/site-packages/wandb/sdk/lib/sock_client.py", line 220, in _read_packet_bytes
    raise SockClientClosedError
wandb.sdk.lib.sock_client.SockClientClosedError

The above exception was the direct cause of the following exception:

Traceback (most recent call last):
  File "/opt/anaconda3/envs/myenv/lib/python3.11/site-packages/wandb/sdk/interface/router.py", line 56, in message_loop
    msg = self._read_message()
          ^^^^^^^^^^^^^^^^^^^^
  File "/opt/anaconda3/envs/myenv/lib/python3.11/site-packages/wandb/sdk/interface/router_sock.py", line 29, in _read_message
    raise MessageRouterClosedError from e
wandb.sdk.interface.router.MessageRouterClosedError
2025-07-03 01:19:28,436 INFO    MsgRouterThr:54956 [mailbox.py:close():129] [no run ID] Closing mailbox, abandoning 1 handles.
