2025-07-03 10:59:32,844 INFO    MainThread:61453 [wandb_setup.py:_flush():81] Current SDK version is 0.20.0
2025-07-03 10:59:32,845 INFO    MainThread:61453 [wandb_setup.py:_flush():81] Configure stats pid to 61453
2025-07-03 10:59:32,845 INFO    MainThread:61453 [wandb_setup.py:_flush():81] Loading settings from /Users/nbhsbgnb/.config/wandb/settings
2025-07-03 10:59:32,845 INFO    MainThread:61453 [wandb_setup.py:_flush():81] Loading settings from /Users/nbhsbgnb/PycharmProjects/PythonProject/PowerPINN/wandb/settings
2025-07-03 10:59:32,845 INFO    MainThread:61453 [wandb_setup.py:_flush():81] Loading settings from environment variables
2025-07-03 10:59:32,845 INFO    MainThread:61453 [wandb_init.py:setup_run_log_directory():703] Logging user logs to /Users/nbhsbgnb/PycharmProjects/PythonProject/PowerPINN/wandb/run-20250703_105932-4zmb6ccd/logs/debug.log
2025-07-03 10:59:32,845 INFO    MainThread:61453 [wandb_init.py:setup_run_log_directory():704] Logging internal logs to /Users/nbhsbgnb/PycharmProjects/PythonProject/PowerPINN/wandb/run-20250703_105932-4zmb6ccd/logs/debug-internal.log
2025-07-03 10:59:32,845 INFO    MainThread:61453 [wandb_init.py:init():831] calling init triggers
2025-07-03 10:59:32,845 INFO    MainThread:61453 [wandb_init.py:init():836] wandb.init called with sweep_config: {}
config: {'_wandb': {}}
2025-07-03 10:59:32,845 INFO    MainThread:61453 [wandb_init.py:init():872] starting backend
2025-07-03 10:59:33,277 INFO    MainThread:61453 [wandb_init.py:init():875] sending inform_init request
2025-07-03 10:59:33,296 INFO    MainThread:61453 [wandb_init.py:init():883] backend started and connected
2025-07-03 10:59:33,298 INFO    MainThread:61453 [wandb_init.py:init():956] updated telemetry
2025-07-03 10:59:33,313 INFO    MainThread:61453 [wandb_init.py:init():980] communicating run to backend with 90.0 second timeout
2025-07-03 10:59:47,115 WARNING MainThread:61453 [wandb_init.py:init():1613] [no run ID] interrupted
Traceback (most recent call last):
  File "/opt/anaconda3/envs/myenv/lib/python3.11/site-packages/wandb/sdk/wandb_init.py", line 1609, in init
    return wi.init(run_settings, run_config, run_printer)
           ^^^^^^^^^^^^^^^^^^^^^^^^^^^^^^^^^^^^^^^^^^^^^^
  File "/opt/anaconda3/envs/myenv/lib/python3.11/site-packages/wandb/sdk/wandb_init.py", line 999, in init
    result = wait_with_progress(
             ^^^^^^^^^^^^^^^^^^^
  File "/opt/anaconda3/envs/myenv/lib/python3.11/site-packages/wandb/sdk/mailbox/wait_with_progress.py", line 24, in wait_with_progress
    return wait_all_with_progress(
           ^^^^^^^^^^^^^^^^^^^^^^^
  File "/opt/anaconda3/envs/myenv/lib/python3.11/site-packages/wandb/sdk/mailbox/wait_with_progress.py", line 87, in wait_all_with_progress
    return asyncio_compat.run(progress_loop_with_timeout)
           ^^^^^^^^^^^^^^^^^^^^^^^^^^^^^^^^^^^^^^^^^^^^^^
  File "/opt/anaconda3/envs/myenv/lib/python3.11/site-packages/wandb/sdk/lib/asyncio_compat.py", line 30, in run
    return future.result()
           ^^^^^^^^^^^^^^^
  File "/opt/anaconda3/envs/myenv/lib/python3.11/concurrent/futures/_base.py", line 451, in result
    self._condition.wait(timeout)
  File "/opt/anaconda3/envs/myenv/lib/python3.11/threading.py", line 327, in wait
    waiter.acquire()
KeyboardInterrupt
2025-07-03 10:59:47,116 WARNING MsgRouterThr:61453 [router.py:message_loop():63] [no run ID] message_loop has been closed
Traceback (most recent call last):
  File "/opt/anaconda3/envs/myenv/lib/python3.11/site-packages/wandb/sdk/interface/router_sock.py", line 27, in _read_message
    return self._sock_client.read_server_response(timeout=1)
           ^^^^^^^^^^^^^^^^^^^^^^^^^^^^^^^^^^^^^^^^^^^^^^^^^
  File "/opt/anaconda3/envs/myenv/lib/python3.11/site-packages/wandb/sdk/lib/sock_client.py", line 235, in read_server_response
    data = self._read_packet_bytes(timeout=timeout)
           ^^^^^^^^^^^^^^^^^^^^^^^^^^^^^^^^^^^^^^^^
  File "/opt/anaconda3/envs/myenv/lib/python3.11/site-packages/wandb/sdk/lib/sock_client.py", line 220, in _read_packet_bytes
    raise SockClientClosedError
wandb.sdk.lib.sock_client.SockClientClosedError

The above exception was the direct cause of the following exception:

Traceback (most recent call last):
  File "/opt/anaconda3/envs/myenv/lib/python3.11/site-packages/wandb/sdk/interface/router.py", line 56, in message_loop
    msg = self._read_message()
          ^^^^^^^^^^^^^^^^^^^^
  File "/opt/anaconda3/envs/myenv/lib/python3.11/site-packages/wandb/sdk/interface/router_sock.py", line 29, in _read_message
    raise MessageRouterClosedError from e
wandb.sdk.interface.router.MessageRouterClosedError
2025-07-03 10:59:47,119 INFO    MsgRouterThr:61453 [mailbox.py:close():129] [no run ID] Closing mailbox, abandoning 2 handles.
