2025-07-16 00:24:06,708 INFO    Thread-2 (_run_job):59013 [wandb_setup.py:_flush():81] Current SDK version is 0.20.0
2025-07-16 00:24:06,708 INFO    Thread-2 (_run_job):59013 [wandb_setup.py:_flush():81] Configure stats pid to 59013
2025-07-16 00:24:06,708 INFO    Thread-2 (_run_job):59013 [wandb_setup.py:_flush():81] Loading settings from /Users/nbhsbgnb/.config/wandb/settings
2025-07-16 00:24:06,708 INFO    Thread-2 (_run_job):59013 [wandb_setup.py:_flush():81] Loading settings from /Users/nbhsbgnb/PycharmProjects/PythonProject/PowerPINN/wandb/settings
2025-07-16 00:24:06,708 INFO    Thread-2 (_run_job):59013 [wandb_setup.py:_flush():81] Loading settings from environment variables
2025-07-16 00:24:06,708 INFO    Thread-2 (_run_job):59013 [wandb_init.py:setup_run_log_directory():703] Logging user logs to /Users/nbhsbgnb/PycharmProjects/PythonProject/PowerPINN/wandb/run-20250716_002406-0jsog8nf/logs/debug.log
2025-07-16 00:24:06,708 INFO    Thread-2 (_run_job):59013 [wandb_init.py:setup_run_log_directory():704] Logging internal logs to /Users/nbhsbgnb/PycharmProjects/PythonProject/PowerPINN/wandb/run-20250716_002406-0jsog8nf/logs/debug-internal.log
2025-07-16 00:24:06,709 INFO    Thread-2 (_run_job):59013 [wandb_init.py:init():831] calling init triggers
2025-07-16 00:24:06,709 INFO    Thread-2 (_run_job):59013 [wandb_init.py:init():836] wandb.init called with sweep_config: {'seed': 1, 'weight_data': 1, 'weight_dt': 0, 'weight_pinn': 0, 'weight_pinn_ic': 0}
config: {'_wandb': {}}
2025-07-16 00:24:06,709 INFO    Thread-2 (_run_job):59013 [wandb_init.py:init():872] starting backend
2025-07-16 00:24:06,936 INFO    Thread-2 (_run_job):59013 [wandb_init.py:init():875] sending inform_init request
2025-07-16 00:24:06,954 INFO    Thread-2 (_run_job):59013 [wandb_init.py:init():883] backend started and connected
2025-07-16 00:24:06,955 INFO    Thread-2 (_run_job):59013 [wandb_run.py:_config_callback():1358] config_cb None None {'seed': 1, 'weight_data': 1, 'weight_dt': 0, 'weight_pinn': 0, 'weight_pinn_ic': 0}
2025-07-16 00:24:06,956 INFO    Thread-2 (_run_job):59013 [wandb_init.py:init():956] updated telemetry
2025-07-16 00:24:06,972 INFO    Thread-2 (_run_job):59013 [wandb_init.py:init():980] communicating run to backend with 90.0 second timeout
2025-07-16 00:24:07,695 INFO    Thread-2 (_run_job):59013 [wandb_init.py:init():1032] starting run threads in backend
2025-07-16 00:24:07,738 INFO    Thread-2 (_run_job):59013 [wandb_run.py:_console_start():2453] atexit reg
2025-07-16 00:24:07,738 INFO    Thread-2 (_run_job):59013 [wandb_run.py:_redirect():2301] redirect: wrap_raw
2025-07-16 00:24:07,739 INFO    Thread-2 (_run_job):59013 [wandb_run.py:_redirect():2370] Wrapping output streams.
2025-07-16 00:24:07,739 INFO    Thread-2 (_run_job):59013 [wandb_run.py:_redirect():2393] Redirects installed.
2025-07-16 00:24:07,740 INFO    Thread-2 (_run_job):59013 [wandb_init.py:init():1078] run started, returning control to user process
2025-07-16 00:51:22,406 INFO    Thread-1 (_heartbeat):59013 [retry.py:__call__():173] [no run ID] Retry attempt failed:
Traceback (most recent call last):
  File "/opt/anaconda3/envs/myenv/lib/python3.11/site-packages/urllib3/connection.py", line 198, in _new_conn
    sock = connection.create_connection(
           ^^^^^^^^^^^^^^^^^^^^^^^^^^^^^
  File "/opt/anaconda3/envs/myenv/lib/python3.11/site-packages/urllib3/util/connection.py", line 60, in create_connection
    for res in socket.getaddrinfo(host, port, family, socket.SOCK_STREAM):
               ^^^^^^^^^^^^^^^^^^^^^^^^^^^^^^^^^^^^^^^^^^^^^^^^^^^^^^^^^^
  File "/opt/anaconda3/envs/myenv/lib/python3.11/socket.py", line 974, in getaddrinfo
    for res in _socket.getaddrinfo(host, port, family, type, proto, flags):
               ^^^^^^^^^^^^^^^^^^^^^^^^^^^^^^^^^^^^^^^^^^^^^^^^^^^^^^^^^^^
socket.gaierror: [Errno 8] nodename nor servname provided, or not known

The above exception was the direct cause of the following exception:

Traceback (most recent call last):
  File "/opt/anaconda3/envs/myenv/lib/python3.11/site-packages/urllib3/connectionpool.py", line 787, in urlopen
    response = self._make_request(
               ^^^^^^^^^^^^^^^^^^^
  File "/opt/anaconda3/envs/myenv/lib/python3.11/site-packages/urllib3/connectionpool.py", line 488, in _make_request
    raise new_e
  File "/opt/anaconda3/envs/myenv/lib/python3.11/site-packages/urllib3/connectionpool.py", line 464, in _make_request
    self._validate_conn(conn)
  File "/opt/anaconda3/envs/myenv/lib/python3.11/site-packages/urllib3/connectionpool.py", line 1093, in _validate_conn
    conn.connect()
  File "/opt/anaconda3/envs/myenv/lib/python3.11/site-packages/urllib3/connection.py", line 704, in connect
    self.sock = sock = self._new_conn()
                       ^^^^^^^^^^^^^^^^
  File "/opt/anaconda3/envs/myenv/lib/python3.11/site-packages/urllib3/connection.py", line 205, in _new_conn
    raise NameResolutionError(self.host, self, e) from e
urllib3.exceptions.NameResolutionError: <urllib3.connection.HTTPSConnection object at 0x166368590>: Failed to resolve 'api.wandb.ai' ([Errno 8] nodename nor servname provided, or not known)

The above exception was the direct cause of the following exception:

Traceback (most recent call last):
  File "/opt/anaconda3/envs/myenv/lib/python3.11/site-packages/requests/adapters.py", line 667, in send
    resp = conn.urlopen(
           ^^^^^^^^^^^^^
  File "/opt/anaconda3/envs/myenv/lib/python3.11/site-packages/urllib3/connectionpool.py", line 841, in urlopen
    retries = retries.increment(
              ^^^^^^^^^^^^^^^^^^
  File "/opt/anaconda3/envs/myenv/lib/python3.11/site-packages/urllib3/util/retry.py", line 519, in increment
    raise MaxRetryError(_pool, url, reason) from reason  # type: ignore[arg-type]
    ^^^^^^^^^^^^^^^^^^^^^^^^^^^^^^^^^^^^^^^^^^^^^^^^^^^
urllib3.exceptions.MaxRetryError: HTTPSConnectionPool(host='api.wandb.ai', port=443): Max retries exceeded with url: /graphql (Caused by NameResolutionError("<urllib3.connection.HTTPSConnection object at 0x166368590>: Failed to resolve 'api.wandb.ai' ([Errno 8] nodename nor servname provided, or not known)"))

During handling of the above exception, another exception occurred:

Traceback (most recent call last):
  File "/opt/anaconda3/envs/myenv/lib/python3.11/site-packages/wandb/sdk/lib/retry.py", line 134, in __call__
    result = self._call_fn(*args, **kwargs)
             ^^^^^^^^^^^^^^^^^^^^^^^^^^^^^^
  File "/opt/anaconda3/envs/myenv/lib/python3.11/site-packages/wandb/sdk/internal/internal_api.py", line 396, in execute
    return self.client.execute(*args, **kwargs)  # type: ignore
           ^^^^^^^^^^^^^^^^^^^^^^^^^^^^^^^^^^^^
  File "/opt/anaconda3/envs/myenv/lib/python3.11/site-packages/wandb/vendor/gql-0.2.0/wandb_gql/client.py", line 52, in execute
    result = self._get_result(document, *args, **kwargs)
             ^^^^^^^^^^^^^^^^^^^^^^^^^^^^^^^^^^^^^^^^^^^
  File "/opt/anaconda3/envs/myenv/lib/python3.11/site-packages/wandb/vendor/gql-0.2.0/wandb_gql/client.py", line 60, in _get_result
    return self.transport.execute(document, *args, **kwargs)
           ^^^^^^^^^^^^^^^^^^^^^^^^^^^^^^^^^^^^^^^^^^^^^^^^^
  File "/opt/anaconda3/envs/myenv/lib/python3.11/site-packages/wandb/sdk/lib/gql_request.py", line 58, in execute
    request = self.session.post(self.url, **post_args)
              ^^^^^^^^^^^^^^^^^^^^^^^^^^^^^^^^^^^^^^^^
  File "/opt/anaconda3/envs/myenv/lib/python3.11/site-packages/requests/sessions.py", line 637, in post
    return self.request("POST", url, data=data, json=json, **kwargs)
           ^^^^^^^^^^^^^^^^^^^^^^^^^^^^^^^^^^^^^^^^^^^^^^^^^^^^^^^^^
  File "/opt/anaconda3/envs/myenv/lib/python3.11/site-packages/requests/sessions.py", line 589, in request
    resp = self.send(prep, **send_kwargs)
           ^^^^^^^^^^^^^^^^^^^^^^^^^^^^^^
  File "/opt/anaconda3/envs/myenv/lib/python3.11/site-packages/requests/sessions.py", line 703, in send
    r = adapter.send(request, **kwargs)
        ^^^^^^^^^^^^^^^^^^^^^^^^^^^^^^^
  File "/opt/anaconda3/envs/myenv/lib/python3.11/site-packages/requests/adapters.py", line 700, in send
    raise ConnectionError(e, request=request)
requests.exceptions.ConnectionError: HTTPSConnectionPool(host='api.wandb.ai', port=443): Max retries exceeded with url: /graphql (Caused by NameResolutionError("<urllib3.connection.HTTPSConnection object at 0x166368590>: Failed to resolve 'api.wandb.ai' ([Errno 8] nodename nor servname provided, or not known)"))
2025-07-16 11:32:13,012 WARNING MsgRouterThr:59013 [router.py:message_loop():63] [no run ID] message_loop has been closed
Traceback (most recent call last):
  File "/opt/anaconda3/envs/myenv/lib/python3.11/site-packages/wandb/sdk/lib/sock_client.py", line 208, in _read_packet_bytes
    data = self._sock.recv(self._bufsize)
           ^^^^^^^^^^^^^^^^^^^^^^^^^^^^^^
ConnectionResetError: [Errno 54] Connection reset by peer

The above exception was the direct cause of the following exception:

Traceback (most recent call last):
  File "/opt/anaconda3/envs/myenv/lib/python3.11/site-packages/wandb/sdk/interface/router_sock.py", line 27, in _read_message
    return self._sock_client.read_server_response(timeout=1)
           ^^^^^^^^^^^^^^^^^^^^^^^^^^^^^^^^^^^^^^^^^^^^^^^^^
  File "/opt/anaconda3/envs/myenv/lib/python3.11/site-packages/wandb/sdk/lib/sock_client.py", line 235, in read_server_response
    data = self._read_packet_bytes(timeout=timeout)
           ^^^^^^^^^^^^^^^^^^^^^^^^^^^^^^^^^^^^^^^^
  File "/opt/anaconda3/envs/myenv/lib/python3.11/site-packages/wandb/sdk/lib/sock_client.py", line 212, in _read_packet_bytes
    raise SockClientClosedError from e
wandb.sdk.lib.sock_client.SockClientClosedError

The above exception was the direct cause of the following exception:

Traceback (most recent call last):
  File "/opt/anaconda3/envs/myenv/lib/python3.11/site-packages/wandb/sdk/interface/router.py", line 56, in message_loop
    msg = self._read_message()
          ^^^^^^^^^^^^^^^^^^^^
  File "/opt/anaconda3/envs/myenv/lib/python3.11/site-packages/wandb/sdk/interface/router_sock.py", line 29, in _read_message
    raise MessageRouterClosedError from e
wandb.sdk.interface.router.MessageRouterClosedError
2025-07-16 11:32:13,052 INFO    MsgRouterThr:59013 [mailbox.py:close():129] [no run ID] Closing mailbox, abandoning 1 handles.
2025-07-16 11:32:13,054 ERROR   MainThread:59013 [redirect.py:_on_write():664] [no run ID] error in stderr callback
Traceback (most recent call last):
  File "/opt/anaconda3/envs/myenv/lib/python3.11/site-packages/wandb/sdk/lib/redirect.py", line 662, in _on_write
    cb(written_data)
  File "/opt/anaconda3/envs/myenv/lib/python3.11/site-packages/wandb/sdk/wandb_run.py", line 2380, in <lambda>
    lambda data: self._console_raw_callback("stderr", data),
                 ^^^^^^^^^^^^^^^^^^^^^^^^^^^^^^^^^^^^^^^^^^
  File "/opt/anaconda3/envs/myenv/lib/python3.11/site-packages/wandb/sdk/wandb_run.py", line 391, in wrapper
    return func(self, *args, **kwargs)
           ^^^^^^^^^^^^^^^^^^^^^^^^^^^
  File "/opt/anaconda3/envs/myenv/lib/python3.11/site-packages/wandb/sdk/wandb_run.py", line 449, in wrapper_fn
    return func(self, *args, **kwargs)
           ^^^^^^^^^^^^^^^^^^^^^^^^^^^
  File "/opt/anaconda3/envs/myenv/lib/python3.11/site-packages/wandb/sdk/wandb_run.py", line 1561, in _console_raw_callback
    self._backend.interface.publish_output_raw(name, data)
  File "/opt/anaconda3/envs/myenv/lib/python3.11/site-packages/wandb/sdk/interface/interface.py", line 772, in publish_output_raw
    self._publish_output_raw(o)
  File "/opt/anaconda3/envs/myenv/lib/python3.11/site-packages/wandb/sdk/interface/interface_shared.py", line 38, in _publish_output_raw
    self._publish(rec)
  File "/opt/anaconda3/envs/myenv/lib/python3.11/site-packages/wandb/sdk/interface/interface_sock.py", line 39, in _publish
    self._sock_client.send_record_publish(record)
  File "/opt/anaconda3/envs/myenv/lib/python3.11/site-packages/wandb/sdk/lib/sock_client.py", line 174, in send_record_publish
    self.send_server_request(server_req)
  File "/opt/anaconda3/envs/myenv/lib/python3.11/site-packages/wandb/sdk/lib/sock_client.py", line 154, in send_server_request
    self._send_message(msg)
  File "/opt/anaconda3/envs/myenv/lib/python3.11/site-packages/wandb/sdk/lib/sock_client.py", line 151, in _send_message
    self._sendall_with_error_handle(header + data)
  File "/opt/anaconda3/envs/myenv/lib/python3.11/site-packages/wandb/sdk/lib/sock_client.py", line 130, in _sendall_with_error_handle
    sent = self._sock.send(data)
           ^^^^^^^^^^^^^^^^^^^^^
BrokenPipeError: [Errno 32] Broken pipe
2025-07-16 11:32:13,079 ERROR   MainThread:59013 [redirect.py:_on_write():664] [no run ID] error in stderr callback
Traceback (most recent call last):
  File "/opt/anaconda3/envs/myenv/lib/python3.11/site-packages/wandb/sdk/lib/redirect.py", line 662, in _on_write
    cb(written_data)
  File "/opt/anaconda3/envs/myenv/lib/python3.11/site-packages/wandb/sdk/wandb_run.py", line 2380, in <lambda>
    lambda data: self._console_raw_callback("stderr", data),
                 ^^^^^^^^^^^^^^^^^^^^^^^^^^^^^^^^^^^^^^^^^^
  File "/opt/anaconda3/envs/myenv/lib/python3.11/site-packages/wandb/sdk/wandb_run.py", line 391, in wrapper
    return func(self, *args, **kwargs)
           ^^^^^^^^^^^^^^^^^^^^^^^^^^^
  File "/opt/anaconda3/envs/myenv/lib/python3.11/site-packages/wandb/sdk/wandb_run.py", line 449, in wrapper_fn
    return func(self, *args, **kwargs)
           ^^^^^^^^^^^^^^^^^^^^^^^^^^^
  File "/opt/anaconda3/envs/myenv/lib/python3.11/site-packages/wandb/sdk/wandb_run.py", line 1561, in _console_raw_callback
    self._backend.interface.publish_output_raw(name, data)
  File "/opt/anaconda3/envs/myenv/lib/python3.11/site-packages/wandb/sdk/interface/interface.py", line 772, in publish_output_raw
    self._publish_output_raw(o)
  File "/opt/anaconda3/envs/myenv/lib/python3.11/site-packages/wandb/sdk/interface/interface_shared.py", line 38, in _publish_output_raw
    self._publish(rec)
  File "/opt/anaconda3/envs/myenv/lib/python3.11/site-packages/wandb/sdk/interface/interface_sock.py", line 39, in _publish
    self._sock_client.send_record_publish(record)
  File "/opt/anaconda3/envs/myenv/lib/python3.11/site-packages/wandb/sdk/lib/sock_client.py", line 174, in send_record_publish
    self.send_server_request(server_req)
  File "/opt/anaconda3/envs/myenv/lib/python3.11/site-packages/wandb/sdk/lib/sock_client.py", line 154, in send_server_request
    self._send_message(msg)
  File "/opt/anaconda3/envs/myenv/lib/python3.11/site-packages/wandb/sdk/lib/sock_client.py", line 151, in _send_message
    self._sendall_with_error_handle(header + data)
  File "/opt/anaconda3/envs/myenv/lib/python3.11/site-packages/wandb/sdk/lib/sock_client.py", line 130, in _sendall_with_error_handle
    sent = self._sock.send(data)
           ^^^^^^^^^^^^^^^^^^^^^
BrokenPipeError: [Errno 32] Broken pipe
2025-07-16 11:32:13,080 ERROR   MainThread:59013 [redirect.py:_on_write():664] [no run ID] error in stderr callback
Traceback (most recent call last):
  File "/opt/anaconda3/envs/myenv/lib/python3.11/site-packages/wandb/sdk/lib/redirect.py", line 662, in _on_write
    cb(written_data)
  File "/opt/anaconda3/envs/myenv/lib/python3.11/site-packages/wandb/sdk/wandb_run.py", line 2380, in <lambda>
    lambda data: self._console_raw_callback("stderr", data),
                 ^^^^^^^^^^^^^^^^^^^^^^^^^^^^^^^^^^^^^^^^^^
  File "/opt/anaconda3/envs/myenv/lib/python3.11/site-packages/wandb/sdk/wandb_run.py", line 391, in wrapper
    return func(self, *args, **kwargs)
           ^^^^^^^^^^^^^^^^^^^^^^^^^^^
  File "/opt/anaconda3/envs/myenv/lib/python3.11/site-packages/wandb/sdk/wandb_run.py", line 449, in wrapper_fn
    return func(self, *args, **kwargs)
           ^^^^^^^^^^^^^^^^^^^^^^^^^^^
  File "/opt/anaconda3/envs/myenv/lib/python3.11/site-packages/wandb/sdk/wandb_run.py", line 1561, in _console_raw_callback
    self._backend.interface.publish_output_raw(name, data)
  File "/opt/anaconda3/envs/myenv/lib/python3.11/site-packages/wandb/sdk/interface/interface.py", line 772, in publish_output_raw
    self._publish_output_raw(o)
  File "/opt/anaconda3/envs/myenv/lib/python3.11/site-packages/wandb/sdk/interface/interface_shared.py", line 38, in _publish_output_raw
    self._publish(rec)
  File "/opt/anaconda3/envs/myenv/lib/python3.11/site-packages/wandb/sdk/interface/interface_sock.py", line 39, in _publish
    self._sock_client.send_record_publish(record)
  File "/opt/anaconda3/envs/myenv/lib/python3.11/site-packages/wandb/sdk/lib/sock_client.py", line 174, in send_record_publish
    self.send_server_request(server_req)
  File "/opt/anaconda3/envs/myenv/lib/python3.11/site-packages/wandb/sdk/lib/sock_client.py", line 154, in send_server_request
    self._send_message(msg)
  File "/opt/anaconda3/envs/myenv/lib/python3.11/site-packages/wandb/sdk/lib/sock_client.py", line 151, in _send_message
    self._sendall_with_error_handle(header + data)
  File "/opt/anaconda3/envs/myenv/lib/python3.11/site-packages/wandb/sdk/lib/sock_client.py", line 130, in _sendall_with_error_handle
    sent = self._sock.send(data)
           ^^^^^^^^^^^^^^^^^^^^^
BrokenPipeError: [Errno 32] Broken pipe
2025-07-16 11:32:13,080 ERROR   MainThread:59013 [redirect.py:_on_write():664] [no run ID] error in stderr callback
Traceback (most recent call last):
  File "/opt/anaconda3/envs/myenv/lib/python3.11/site-packages/wandb/sdk/lib/redirect.py", line 662, in _on_write
    cb(written_data)
  File "/opt/anaconda3/envs/myenv/lib/python3.11/site-packages/wandb/sdk/wandb_run.py", line 2380, in <lambda>
    lambda data: self._console_raw_callback("stderr", data),
                 ^^^^^^^^^^^^^^^^^^^^^^^^^^^^^^^^^^^^^^^^^^
  File "/opt/anaconda3/envs/myenv/lib/python3.11/site-packages/wandb/sdk/wandb_run.py", line 391, in wrapper
    return func(self, *args, **kwargs)
           ^^^^^^^^^^^^^^^^^^^^^^^^^^^
  File "/opt/anaconda3/envs/myenv/lib/python3.11/site-packages/wandb/sdk/wandb_run.py", line 449, in wrapper_fn
    return func(self, *args, **kwargs)
           ^^^^^^^^^^^^^^^^^^^^^^^^^^^
  File "/opt/anaconda3/envs/myenv/lib/python3.11/site-packages/wandb/sdk/wandb_run.py", line 1561, in _console_raw_callback
    self._backend.interface.publish_output_raw(name, data)
  File "/opt/anaconda3/envs/myenv/lib/python3.11/site-packages/wandb/sdk/interface/interface.py", line 772, in publish_output_raw
    self._publish_output_raw(o)
  File "/opt/anaconda3/envs/myenv/lib/python3.11/site-packages/wandb/sdk/interface/interface_shared.py", line 38, in _publish_output_raw
    self._publish(rec)
  File "/opt/anaconda3/envs/myenv/lib/python3.11/site-packages/wandb/sdk/interface/interface_sock.py", line 39, in _publish
    self._sock_client.send_record_publish(record)
  File "/opt/anaconda3/envs/myenv/lib/python3.11/site-packages/wandb/sdk/lib/sock_client.py", line 174, in send_record_publish
    self.send_server_request(server_req)
  File "/opt/anaconda3/envs/myenv/lib/python3.11/site-packages/wandb/sdk/lib/sock_client.py", line 154, in send_server_request
    self._send_message(msg)
  File "/opt/anaconda3/envs/myenv/lib/python3.11/site-packages/wandb/sdk/lib/sock_client.py", line 151, in _send_message
    self._sendall_with_error_handle(header + data)
  File "/opt/anaconda3/envs/myenv/lib/python3.11/site-packages/wandb/sdk/lib/sock_client.py", line 130, in _sendall_with_error_handle
    sent = self._sock.send(data)
           ^^^^^^^^^^^^^^^^^^^^^
BrokenPipeError: [Errno 32] Broken pipe
2025-07-16 11:32:13,085 ERROR   MainThread:59013 [redirect.py:_on_write():664] [no run ID] error in stderr callback
Traceback (most recent call last):
  File "/opt/anaconda3/envs/myenv/lib/python3.11/site-packages/wandb/sdk/lib/redirect.py", line 662, in _on_write
    cb(written_data)
  File "/opt/anaconda3/envs/myenv/lib/python3.11/site-packages/wandb/sdk/wandb_run.py", line 2380, in <lambda>
    lambda data: self._console_raw_callback("stderr", data),
                 ^^^^^^^^^^^^^^^^^^^^^^^^^^^^^^^^^^^^^^^^^^
  File "/opt/anaconda3/envs/myenv/lib/python3.11/site-packages/wandb/sdk/wandb_run.py", line 391, in wrapper
    return func(self, *args, **kwargs)
           ^^^^^^^^^^^^^^^^^^^^^^^^^^^
  File "/opt/anaconda3/envs/myenv/lib/python3.11/site-packages/wandb/sdk/wandb_run.py", line 449, in wrapper_fn
    return func(self, *args, **kwargs)
           ^^^^^^^^^^^^^^^^^^^^^^^^^^^
  File "/opt/anaconda3/envs/myenv/lib/python3.11/site-packages/wandb/sdk/wandb_run.py", line 1561, in _console_raw_callback
    self._backend.interface.publish_output_raw(name, data)
  File "/opt/anaconda3/envs/myenv/lib/python3.11/site-packages/wandb/sdk/interface/interface.py", line 772, in publish_output_raw
    self._publish_output_raw(o)
  File "/opt/anaconda3/envs/myenv/lib/python3.11/site-packages/wandb/sdk/interface/interface_shared.py", line 38, in _publish_output_raw
    self._publish(rec)
  File "/opt/anaconda3/envs/myenv/lib/python3.11/site-packages/wandb/sdk/interface/interface_sock.py", line 39, in _publish
    self._sock_client.send_record_publish(record)
  File "/opt/anaconda3/envs/myenv/lib/python3.11/site-packages/wandb/sdk/lib/sock_client.py", line 174, in send_record_publish
    self.send_server_request(server_req)
  File "/opt/anaconda3/envs/myenv/lib/python3.11/site-packages/wandb/sdk/lib/sock_client.py", line 154, in send_server_request
    self._send_message(msg)
  File "/opt/anaconda3/envs/myenv/lib/python3.11/site-packages/wandb/sdk/lib/sock_client.py", line 151, in _send_message
    self._sendall_with_error_handle(header + data)
  File "/opt/anaconda3/envs/myenv/lib/python3.11/site-packages/wandb/sdk/lib/sock_client.py", line 130, in _sendall_with_error_handle
    sent = self._sock.send(data)
           ^^^^^^^^^^^^^^^^^^^^^
BrokenPipeError: [Errno 32] Broken pipe
2025-07-16 11:32:13,086 ERROR   MainThread:59013 [redirect.py:_on_write():664] [no run ID] error in stderr callback
Traceback (most recent call last):
  File "/opt/anaconda3/envs/myenv/lib/python3.11/site-packages/wandb/sdk/lib/redirect.py", line 662, in _on_write
    cb(written_data)
  File "/opt/anaconda3/envs/myenv/lib/python3.11/site-packages/wandb/sdk/wandb_run.py", line 2380, in <lambda>
    lambda data: self._console_raw_callback("stderr", data),
                 ^^^^^^^^^^^^^^^^^^^^^^^^^^^^^^^^^^^^^^^^^^
  File "/opt/anaconda3/envs/myenv/lib/python3.11/site-packages/wandb/sdk/wandb_run.py", line 391, in wrapper
    return func(self, *args, **kwargs)
           ^^^^^^^^^^^^^^^^^^^^^^^^^^^
  File "/opt/anaconda3/envs/myenv/lib/python3.11/site-packages/wandb/sdk/wandb_run.py", line 449, in wrapper_fn
    return func(self, *args, **kwargs)
           ^^^^^^^^^^^^^^^^^^^^^^^^^^^
  File "/opt/anaconda3/envs/myenv/lib/python3.11/site-packages/wandb/sdk/wandb_run.py", line 1561, in _console_raw_callback
    self._backend.interface.publish_output_raw(name, data)
  File "/opt/anaconda3/envs/myenv/lib/python3.11/site-packages/wandb/sdk/interface/interface.py", line 772, in publish_output_raw
    self._publish_output_raw(o)
  File "/opt/anaconda3/envs/myenv/lib/python3.11/site-packages/wandb/sdk/interface/interface_shared.py", line 38, in _publish_output_raw
    self._publish(rec)
  File "/opt/anaconda3/envs/myenv/lib/python3.11/site-packages/wandb/sdk/interface/interface_sock.py", line 39, in _publish
    self._sock_client.send_record_publish(record)
  File "/opt/anaconda3/envs/myenv/lib/python3.11/site-packages/wandb/sdk/lib/sock_client.py", line 174, in send_record_publish
    self.send_server_request(server_req)
  File "/opt/anaconda3/envs/myenv/lib/python3.11/site-packages/wandb/sdk/lib/sock_client.py", line 154, in send_server_request
    self._send_message(msg)
  File "/opt/anaconda3/envs/myenv/lib/python3.11/site-packages/wandb/sdk/lib/sock_client.py", line 151, in _send_message
    self._sendall_with_error_handle(header + data)
  File "/opt/anaconda3/envs/myenv/lib/python3.11/site-packages/wandb/sdk/lib/sock_client.py", line 130, in _sendall_with_error_handle
    sent = self._sock.send(data)
           ^^^^^^^^^^^^^^^^^^^^^
BrokenPipeError: [Errno 32] Broken pipe
2025-07-16 11:32:13,087 ERROR   MainThread:59013 [redirect.py:_on_write():664] [no run ID] error in stderr callback
Traceback (most recent call last):
  File "/opt/anaconda3/envs/myenv/lib/python3.11/site-packages/wandb/sdk/lib/redirect.py", line 662, in _on_write
    cb(written_data)
  File "/opt/anaconda3/envs/myenv/lib/python3.11/site-packages/wandb/sdk/wandb_run.py", line 2380, in <lambda>
    lambda data: self._console_raw_callback("stderr", data),
                 ^^^^^^^^^^^^^^^^^^^^^^^^^^^^^^^^^^^^^^^^^^
  File "/opt/anaconda3/envs/myenv/lib/python3.11/site-packages/wandb/sdk/wandb_run.py", line 391, in wrapper
    return func(self, *args, **kwargs)
           ^^^^^^^^^^^^^^^^^^^^^^^^^^^
  File "/opt/anaconda3/envs/myenv/lib/python3.11/site-packages/wandb/sdk/wandb_run.py", line 449, in wrapper_fn
    return func(self, *args, **kwargs)
           ^^^^^^^^^^^^^^^^^^^^^^^^^^^
  File "/opt/anaconda3/envs/myenv/lib/python3.11/site-packages/wandb/sdk/wandb_run.py", line 1561, in _console_raw_callback
    self._backend.interface.publish_output_raw(name, data)
  File "/opt/anaconda3/envs/myenv/lib/python3.11/site-packages/wandb/sdk/interface/interface.py", line 772, in publish_output_raw
    self._publish_output_raw(o)
  File "/opt/anaconda3/envs/myenv/lib/python3.11/site-packages/wandb/sdk/interface/interface_shared.py", line 38, in _publish_output_raw
    self._publish(rec)
  File "/opt/anaconda3/envs/myenv/lib/python3.11/site-packages/wandb/sdk/interface/interface_sock.py", line 39, in _publish
    self._sock_client.send_record_publish(record)
  File "/opt/anaconda3/envs/myenv/lib/python3.11/site-packages/wandb/sdk/lib/sock_client.py", line 174, in send_record_publish
    self.send_server_request(server_req)
  File "/opt/anaconda3/envs/myenv/lib/python3.11/site-packages/wandb/sdk/lib/sock_client.py", line 154, in send_server_request
    self._send_message(msg)
  File "/opt/anaconda3/envs/myenv/lib/python3.11/site-packages/wandb/sdk/lib/sock_client.py", line 151, in _send_message
    self._sendall_with_error_handle(header + data)
  File "/opt/anaconda3/envs/myenv/lib/python3.11/site-packages/wandb/sdk/lib/sock_client.py", line 130, in _sendall_with_error_handle
    sent = self._sock.send(data)
           ^^^^^^^^^^^^^^^^^^^^^
BrokenPipeError: [Errno 32] Broken pipe
2025-07-16 11:32:13,088 ERROR   MainThread:59013 [redirect.py:_on_write():664] [no run ID] error in stderr callback
Traceback (most recent call last):
  File "/opt/anaconda3/envs/myenv/lib/python3.11/site-packages/wandb/sdk/lib/redirect.py", line 662, in _on_write
    cb(written_data)
  File "/opt/anaconda3/envs/myenv/lib/python3.11/site-packages/wandb/sdk/wandb_run.py", line 2380, in <lambda>
    lambda data: self._console_raw_callback("stderr", data),
                 ^^^^^^^^^^^^^^^^^^^^^^^^^^^^^^^^^^^^^^^^^^
  File "/opt/anaconda3/envs/myenv/lib/python3.11/site-packages/wandb/sdk/wandb_run.py", line 391, in wrapper
    return func(self, *args, **kwargs)
           ^^^^^^^^^^^^^^^^^^^^^^^^^^^
  File "/opt/anaconda3/envs/myenv/lib/python3.11/site-packages/wandb/sdk/wandb_run.py", line 449, in wrapper_fn
    return func(self, *args, **kwargs)
           ^^^^^^^^^^^^^^^^^^^^^^^^^^^
  File "/opt/anaconda3/envs/myenv/lib/python3.11/site-packages/wandb/sdk/wandb_run.py", line 1561, in _console_raw_callback
    self._backend.interface.publish_output_raw(name, data)
  File "/opt/anaconda3/envs/myenv/lib/python3.11/site-packages/wandb/sdk/interface/interface.py", line 772, in publish_output_raw
    self._publish_output_raw(o)
  File "/opt/anaconda3/envs/myenv/lib/python3.11/site-packages/wandb/sdk/interface/interface_shared.py", line 38, in _publish_output_raw
    self._publish(rec)
  File "/opt/anaconda3/envs/myenv/lib/python3.11/site-packages/wandb/sdk/interface/interface_sock.py", line 39, in _publish
    self._sock_client.send_record_publish(record)
  File "/opt/anaconda3/envs/myenv/lib/python3.11/site-packages/wandb/sdk/lib/sock_client.py", line 174, in send_record_publish
    self.send_server_request(server_req)
  File "/opt/anaconda3/envs/myenv/lib/python3.11/site-packages/wandb/sdk/lib/sock_client.py", line 154, in send_server_request
    self._send_message(msg)
  File "/opt/anaconda3/envs/myenv/lib/python3.11/site-packages/wandb/sdk/lib/sock_client.py", line 151, in _send_message
    self._sendall_with_error_handle(header + data)
  File "/opt/anaconda3/envs/myenv/lib/python3.11/site-packages/wandb/sdk/lib/sock_client.py", line 130, in _sendall_with_error_handle
    sent = self._sock.send(data)
           ^^^^^^^^^^^^^^^^^^^^^
BrokenPipeError: [Errno 32] Broken pipe
2025-07-16 11:32:13,091 ERROR   MainThread:59013 [redirect.py:_on_write():664] [no run ID] error in stderr callback
Traceback (most recent call last):
  File "/opt/anaconda3/envs/myenv/lib/python3.11/site-packages/wandb/sdk/lib/redirect.py", line 662, in _on_write
    cb(written_data)
  File "/opt/anaconda3/envs/myenv/lib/python3.11/site-packages/wandb/sdk/wandb_run.py", line 2380, in <lambda>
    lambda data: self._console_raw_callback("stderr", data),
                 ^^^^^^^^^^^^^^^^^^^^^^^^^^^^^^^^^^^^^^^^^^
  File "/opt/anaconda3/envs/myenv/lib/python3.11/site-packages/wandb/sdk/wandb_run.py", line 391, in wrapper
    return func(self, *args, **kwargs)
           ^^^^^^^^^^^^^^^^^^^^^^^^^^^
  File "/opt/anaconda3/envs/myenv/lib/python3.11/site-packages/wandb/sdk/wandb_run.py", line 449, in wrapper_fn
    return func(self, *args, **kwargs)
           ^^^^^^^^^^^^^^^^^^^^^^^^^^^
  File "/opt/anaconda3/envs/myenv/lib/python3.11/site-packages/wandb/sdk/wandb_run.py", line 1561, in _console_raw_callback
    self._backend.interface.publish_output_raw(name, data)
  File "/opt/anaconda3/envs/myenv/lib/python3.11/site-packages/wandb/sdk/interface/interface.py", line 772, in publish_output_raw
    self._publish_output_raw(o)
  File "/opt/anaconda3/envs/myenv/lib/python3.11/site-packages/wandb/sdk/interface/interface_shared.py", line 38, in _publish_output_raw
    self._publish(rec)
  File "/opt/anaconda3/envs/myenv/lib/python3.11/site-packages/wandb/sdk/interface/interface_sock.py", line 39, in _publish
    self._sock_client.send_record_publish(record)
  File "/opt/anaconda3/envs/myenv/lib/python3.11/site-packages/wandb/sdk/lib/sock_client.py", line 174, in send_record_publish
    self.send_server_request(server_req)
  File "/opt/anaconda3/envs/myenv/lib/python3.11/site-packages/wandb/sdk/lib/sock_client.py", line 154, in send_server_request
    self._send_message(msg)
  File "/opt/anaconda3/envs/myenv/lib/python3.11/site-packages/wandb/sdk/lib/sock_client.py", line 151, in _send_message
    self._sendall_with_error_handle(header + data)
  File "/opt/anaconda3/envs/myenv/lib/python3.11/site-packages/wandb/sdk/lib/sock_client.py", line 130, in _sendall_with_error_handle
    sent = self._sock.send(data)
           ^^^^^^^^^^^^^^^^^^^^^
BrokenPipeError: [Errno 32] Broken pipe
2025-07-16 11:32:13,139 ERROR   MainThread:59013 [redirect.py:_on_write():664] [no run ID] error in stderr callback
Traceback (most recent call last):
  File "/opt/anaconda3/envs/myenv/lib/python3.11/site-packages/wandb/sdk/lib/redirect.py", line 662, in _on_write
    cb(written_data)
  File "/opt/anaconda3/envs/myenv/lib/python3.11/site-packages/wandb/sdk/wandb_run.py", line 2380, in <lambda>
    lambda data: self._console_raw_callback("stderr", data),
                 ^^^^^^^^^^^^^^^^^^^^^^^^^^^^^^^^^^^^^^^^^^
  File "/opt/anaconda3/envs/myenv/lib/python3.11/site-packages/wandb/sdk/wandb_run.py", line 391, in wrapper
    return func(self, *args, **kwargs)
           ^^^^^^^^^^^^^^^^^^^^^^^^^^^
  File "/opt/anaconda3/envs/myenv/lib/python3.11/site-packages/wandb/sdk/wandb_run.py", line 449, in wrapper_fn
    return func(self, *args, **kwargs)
           ^^^^^^^^^^^^^^^^^^^^^^^^^^^
  File "/opt/anaconda3/envs/myenv/lib/python3.11/site-packages/wandb/sdk/wandb_run.py", line 1561, in _console_raw_callback
    self._backend.interface.publish_output_raw(name, data)
  File "/opt/anaconda3/envs/myenv/lib/python3.11/site-packages/wandb/sdk/interface/interface.py", line 772, in publish_output_raw
    self._publish_output_raw(o)
  File "/opt/anaconda3/envs/myenv/lib/python3.11/site-packages/wandb/sdk/interface/interface_shared.py", line 38, in _publish_output_raw
    self._publish(rec)
  File "/opt/anaconda3/envs/myenv/lib/python3.11/site-packages/wandb/sdk/interface/interface_sock.py", line 39, in _publish
    self._sock_client.send_record_publish(record)
  File "/opt/anaconda3/envs/myenv/lib/python3.11/site-packages/wandb/sdk/lib/sock_client.py", line 174, in send_record_publish
    self.send_server_request(server_req)
  File "/opt/anaconda3/envs/myenv/lib/python3.11/site-packages/wandb/sdk/lib/sock_client.py", line 154, in send_server_request
    self._send_message(msg)
  File "/opt/anaconda3/envs/myenv/lib/python3.11/site-packages/wandb/sdk/lib/sock_client.py", line 151, in _send_message
    self._sendall_with_error_handle(header + data)
  File "/opt/anaconda3/envs/myenv/lib/python3.11/site-packages/wandb/sdk/lib/sock_client.py", line 130, in _sendall_with_error_handle
    sent = self._sock.send(data)
           ^^^^^^^^^^^^^^^^^^^^^
BrokenPipeError: [Errno 32] Broken pipe
2025-07-16 11:32:13,140 ERROR   MainThread:59013 [redirect.py:_on_write():664] [no run ID] error in stderr callback
Traceback (most recent call last):
  File "/opt/anaconda3/envs/myenv/lib/python3.11/site-packages/wandb/sdk/lib/redirect.py", line 662, in _on_write
    cb(written_data)
  File "/opt/anaconda3/envs/myenv/lib/python3.11/site-packages/wandb/sdk/wandb_run.py", line 2380, in <lambda>
    lambda data: self._console_raw_callback("stderr", data),
                 ^^^^^^^^^^^^^^^^^^^^^^^^^^^^^^^^^^^^^^^^^^
  File "/opt/anaconda3/envs/myenv/lib/python3.11/site-packages/wandb/sdk/wandb_run.py", line 391, in wrapper
    return func(self, *args, **kwargs)
           ^^^^^^^^^^^^^^^^^^^^^^^^^^^
  File "/opt/anaconda3/envs/myenv/lib/python3.11/site-packages/wandb/sdk/wandb_run.py", line 449, in wrapper_fn
    return func(self, *args, **kwargs)
           ^^^^^^^^^^^^^^^^^^^^^^^^^^^
  File "/opt/anaconda3/envs/myenv/lib/python3.11/site-packages/wandb/sdk/wandb_run.py", line 1561, in _console_raw_callback
    self._backend.interface.publish_output_raw(name, data)
  File "/opt/anaconda3/envs/myenv/lib/python3.11/site-packages/wandb/sdk/interface/interface.py", line 772, in publish_output_raw
    self._publish_output_raw(o)
  File "/opt/anaconda3/envs/myenv/lib/python3.11/site-packages/wandb/sdk/interface/interface_shared.py", line 38, in _publish_output_raw
    self._publish(rec)
  File "/opt/anaconda3/envs/myenv/lib/python3.11/site-packages/wandb/sdk/interface/interface_sock.py", line 39, in _publish
    self._sock_client.send_record_publish(record)
  File "/opt/anaconda3/envs/myenv/lib/python3.11/site-packages/wandb/sdk/lib/sock_client.py", line 174, in send_record_publish
    self.send_server_request(server_req)
  File "/opt/anaconda3/envs/myenv/lib/python3.11/site-packages/wandb/sdk/lib/sock_client.py", line 154, in send_server_request
    self._send_message(msg)
  File "/opt/anaconda3/envs/myenv/lib/python3.11/site-packages/wandb/sdk/lib/sock_client.py", line 151, in _send_message
    self._sendall_with_error_handle(header + data)
  File "/opt/anaconda3/envs/myenv/lib/python3.11/site-packages/wandb/sdk/lib/sock_client.py", line 130, in _sendall_with_error_handle
    sent = self._sock.send(data)
           ^^^^^^^^^^^^^^^^^^^^^
BrokenPipeError: [Errno 32] Broken pipe
2025-07-16 11:32:13,140 ERROR   MainThread:59013 [redirect.py:_on_write():664] [no run ID] error in stderr callback
Traceback (most recent call last):
  File "/opt/anaconda3/envs/myenv/lib/python3.11/site-packages/wandb/sdk/lib/redirect.py", line 662, in _on_write
    cb(written_data)
  File "/opt/anaconda3/envs/myenv/lib/python3.11/site-packages/wandb/sdk/wandb_run.py", line 2380, in <lambda>
    lambda data: self._console_raw_callback("stderr", data),
                 ^^^^^^^^^^^^^^^^^^^^^^^^^^^^^^^^^^^^^^^^^^
  File "/opt/anaconda3/envs/myenv/lib/python3.11/site-packages/wandb/sdk/wandb_run.py", line 391, in wrapper
    return func(self, *args, **kwargs)
           ^^^^^^^^^^^^^^^^^^^^^^^^^^^
  File "/opt/anaconda3/envs/myenv/lib/python3.11/site-packages/wandb/sdk/wandb_run.py", line 449, in wrapper_fn
    return func(self, *args, **kwargs)
           ^^^^^^^^^^^^^^^^^^^^^^^^^^^
  File "/opt/anaconda3/envs/myenv/lib/python3.11/site-packages/wandb/sdk/wandb_run.py", line 1561, in _console_raw_callback
    self._backend.interface.publish_output_raw(name, data)
  File "/opt/anaconda3/envs/myenv/lib/python3.11/site-packages/wandb/sdk/interface/interface.py", line 772, in publish_output_raw
    self._publish_output_raw(o)
  File "/opt/anaconda3/envs/myenv/lib/python3.11/site-packages/wandb/sdk/interface/interface_shared.py", line 38, in _publish_output_raw
    self._publish(rec)
  File "/opt/anaconda3/envs/myenv/lib/python3.11/site-packages/wandb/sdk/interface/interface_sock.py", line 39, in _publish
    self._sock_client.send_record_publish(record)
  File "/opt/anaconda3/envs/myenv/lib/python3.11/site-packages/wandb/sdk/lib/sock_client.py", line 174, in send_record_publish
    self.send_server_request(server_req)
  File "/opt/anaconda3/envs/myenv/lib/python3.11/site-packages/wandb/sdk/lib/sock_client.py", line 154, in send_server_request
    self._send_message(msg)
  File "/opt/anaconda3/envs/myenv/lib/python3.11/site-packages/wandb/sdk/lib/sock_client.py", line 151, in _send_message
    self._sendall_with_error_handle(header + data)
  File "/opt/anaconda3/envs/myenv/lib/python3.11/site-packages/wandb/sdk/lib/sock_client.py", line 130, in _sendall_with_error_handle
    sent = self._sock.send(data)
           ^^^^^^^^^^^^^^^^^^^^^
BrokenPipeError: [Errno 32] Broken pipe
2025-07-16 11:32:13,141 ERROR   MainThread:59013 [redirect.py:_on_write():664] [no run ID] error in stderr callback
Traceback (most recent call last):
  File "/opt/anaconda3/envs/myenv/lib/python3.11/site-packages/wandb/sdk/lib/redirect.py", line 662, in _on_write
    cb(written_data)
  File "/opt/anaconda3/envs/myenv/lib/python3.11/site-packages/wandb/sdk/wandb_run.py", line 2380, in <lambda>
    lambda data: self._console_raw_callback("stderr", data),
                 ^^^^^^^^^^^^^^^^^^^^^^^^^^^^^^^^^^^^^^^^^^
  File "/opt/anaconda3/envs/myenv/lib/python3.11/site-packages/wandb/sdk/wandb_run.py", line 391, in wrapper
    return func(self, *args, **kwargs)
           ^^^^^^^^^^^^^^^^^^^^^^^^^^^
  File "/opt/anaconda3/envs/myenv/lib/python3.11/site-packages/wandb/sdk/wandb_run.py", line 449, in wrapper_fn
    return func(self, *args, **kwargs)
           ^^^^^^^^^^^^^^^^^^^^^^^^^^^
  File "/opt/anaconda3/envs/myenv/lib/python3.11/site-packages/wandb/sdk/wandb_run.py", line 1561, in _console_raw_callback
    self._backend.interface.publish_output_raw(name, data)
  File "/opt/anaconda3/envs/myenv/lib/python3.11/site-packages/wandb/sdk/interface/interface.py", line 772, in publish_output_raw
    self._publish_output_raw(o)
  File "/opt/anaconda3/envs/myenv/lib/python3.11/site-packages/wandb/sdk/interface/interface_shared.py", line 38, in _publish_output_raw
    self._publish(rec)
  File "/opt/anaconda3/envs/myenv/lib/python3.11/site-packages/wandb/sdk/interface/interface_sock.py", line 39, in _publish
    self._sock_client.send_record_publish(record)
  File "/opt/anaconda3/envs/myenv/lib/python3.11/site-packages/wandb/sdk/lib/sock_client.py", line 174, in send_record_publish
    self.send_server_request(server_req)
  File "/opt/anaconda3/envs/myenv/lib/python3.11/site-packages/wandb/sdk/lib/sock_client.py", line 154, in send_server_request
    self._send_message(msg)
  File "/opt/anaconda3/envs/myenv/lib/python3.11/site-packages/wandb/sdk/lib/sock_client.py", line 151, in _send_message
    self._sendall_with_error_handle(header + data)
  File "/opt/anaconda3/envs/myenv/lib/python3.11/site-packages/wandb/sdk/lib/sock_client.py", line 130, in _sendall_with_error_handle
    sent = self._sock.send(data)
           ^^^^^^^^^^^^^^^^^^^^^
BrokenPipeError: [Errno 32] Broken pipe
2025-07-16 11:32:13,143 ERROR   MainThread:59013 [redirect.py:_on_write():664] [no run ID] error in stderr callback
Traceback (most recent call last):
  File "/opt/anaconda3/envs/myenv/lib/python3.11/site-packages/wandb/sdk/lib/redirect.py", line 662, in _on_write
    cb(written_data)
  File "/opt/anaconda3/envs/myenv/lib/python3.11/site-packages/wandb/sdk/wandb_run.py", line 2380, in <lambda>
    lambda data: self._console_raw_callback("stderr", data),
                 ^^^^^^^^^^^^^^^^^^^^^^^^^^^^^^^^^^^^^^^^^^
  File "/opt/anaconda3/envs/myenv/lib/python3.11/site-packages/wandb/sdk/wandb_run.py", line 391, in wrapper
    return func(self, *args, **kwargs)
           ^^^^^^^^^^^^^^^^^^^^^^^^^^^
  File "/opt/anaconda3/envs/myenv/lib/python3.11/site-packages/wandb/sdk/wandb_run.py", line 449, in wrapper_fn
    return func(self, *args, **kwargs)
           ^^^^^^^^^^^^^^^^^^^^^^^^^^^
  File "/opt/anaconda3/envs/myenv/lib/python3.11/site-packages/wandb/sdk/wandb_run.py", line 1561, in _console_raw_callback
    self._backend.interface.publish_output_raw(name, data)
  File "/opt/anaconda3/envs/myenv/lib/python3.11/site-packages/wandb/sdk/interface/interface.py", line 772, in publish_output_raw
    self._publish_output_raw(o)
  File "/opt/anaconda3/envs/myenv/lib/python3.11/site-packages/wandb/sdk/interface/interface_shared.py", line 38, in _publish_output_raw
    self._publish(rec)
  File "/opt/anaconda3/envs/myenv/lib/python3.11/site-packages/wandb/sdk/interface/interface_sock.py", line 39, in _publish
    self._sock_client.send_record_publish(record)
  File "/opt/anaconda3/envs/myenv/lib/python3.11/site-packages/wandb/sdk/lib/sock_client.py", line 174, in send_record_publish
    self.send_server_request(server_req)
  File "/opt/anaconda3/envs/myenv/lib/python3.11/site-packages/wandb/sdk/lib/sock_client.py", line 154, in send_server_request
    self._send_message(msg)
  File "/opt/anaconda3/envs/myenv/lib/python3.11/site-packages/wandb/sdk/lib/sock_client.py", line 151, in _send_message
    self._sendall_with_error_handle(header + data)
  File "/opt/anaconda3/envs/myenv/lib/python3.11/site-packages/wandb/sdk/lib/sock_client.py", line 130, in _sendall_with_error_handle
    sent = self._sock.send(data)
           ^^^^^^^^^^^^^^^^^^^^^
BrokenPipeError: [Errno 32] Broken pipe
2025-07-16 11:32:13,144 ERROR   MainThread:59013 [redirect.py:_on_write():664] [no run ID] error in stderr callback
Traceback (most recent call last):
  File "/opt/anaconda3/envs/myenv/lib/python3.11/site-packages/wandb/sdk/lib/redirect.py", line 662, in _on_write
    cb(written_data)
  File "/opt/anaconda3/envs/myenv/lib/python3.11/site-packages/wandb/sdk/wandb_run.py", line 2380, in <lambda>
    lambda data: self._console_raw_callback("stderr", data),
                 ^^^^^^^^^^^^^^^^^^^^^^^^^^^^^^^^^^^^^^^^^^
  File "/opt/anaconda3/envs/myenv/lib/python3.11/site-packages/wandb/sdk/wandb_run.py", line 391, in wrapper
    return func(self, *args, **kwargs)
           ^^^^^^^^^^^^^^^^^^^^^^^^^^^
  File "/opt/anaconda3/envs/myenv/lib/python3.11/site-packages/wandb/sdk/wandb_run.py", line 449, in wrapper_fn
    return func(self, *args, **kwargs)
           ^^^^^^^^^^^^^^^^^^^^^^^^^^^
  File "/opt/anaconda3/envs/myenv/lib/python3.11/site-packages/wandb/sdk/wandb_run.py", line 1561, in _console_raw_callback
    self._backend.interface.publish_output_raw(name, data)
  File "/opt/anaconda3/envs/myenv/lib/python3.11/site-packages/wandb/sdk/interface/interface.py", line 772, in publish_output_raw
    self._publish_output_raw(o)
  File "/opt/anaconda3/envs/myenv/lib/python3.11/site-packages/wandb/sdk/interface/interface_shared.py", line 38, in _publish_output_raw
    self._publish(rec)
  File "/opt/anaconda3/envs/myenv/lib/python3.11/site-packages/wandb/sdk/interface/interface_sock.py", line 39, in _publish
    self._sock_client.send_record_publish(record)
  File "/opt/anaconda3/envs/myenv/lib/python3.11/site-packages/wandb/sdk/lib/sock_client.py", line 174, in send_record_publish
    self.send_server_request(server_req)
  File "/opt/anaconda3/envs/myenv/lib/python3.11/site-packages/wandb/sdk/lib/sock_client.py", line 154, in send_server_request
    self._send_message(msg)
  File "/opt/anaconda3/envs/myenv/lib/python3.11/site-packages/wandb/sdk/lib/sock_client.py", line 151, in _send_message
    self._sendall_with_error_handle(header + data)
  File "/opt/anaconda3/envs/myenv/lib/python3.11/site-packages/wandb/sdk/lib/sock_client.py", line 130, in _sendall_with_error_handle
    sent = self._sock.send(data)
           ^^^^^^^^^^^^^^^^^^^^^
BrokenPipeError: [Errno 32] Broken pipe
2025-07-16 11:32:13,145 ERROR   MainThread:59013 [redirect.py:_on_write():664] [no run ID] error in stderr callback
Traceback (most recent call last):
  File "/opt/anaconda3/envs/myenv/lib/python3.11/site-packages/wandb/sdk/lib/redirect.py", line 662, in _on_write
    cb(written_data)
  File "/opt/anaconda3/envs/myenv/lib/python3.11/site-packages/wandb/sdk/wandb_run.py", line 2380, in <lambda>
    lambda data: self._console_raw_callback("stderr", data),
                 ^^^^^^^^^^^^^^^^^^^^^^^^^^^^^^^^^^^^^^^^^^
  File "/opt/anaconda3/envs/myenv/lib/python3.11/site-packages/wandb/sdk/wandb_run.py", line 391, in wrapper
    return func(self, *args, **kwargs)
           ^^^^^^^^^^^^^^^^^^^^^^^^^^^
  File "/opt/anaconda3/envs/myenv/lib/python3.11/site-packages/wandb/sdk/wandb_run.py", line 449, in wrapper_fn
    return func(self, *args, **kwargs)
           ^^^^^^^^^^^^^^^^^^^^^^^^^^^
  File "/opt/anaconda3/envs/myenv/lib/python3.11/site-packages/wandb/sdk/wandb_run.py", line 1561, in _console_raw_callback
    self._backend.interface.publish_output_raw(name, data)
  File "/opt/anaconda3/envs/myenv/lib/python3.11/site-packages/wandb/sdk/interface/interface.py", line 772, in publish_output_raw
    self._publish_output_raw(o)
  File "/opt/anaconda3/envs/myenv/lib/python3.11/site-packages/wandb/sdk/interface/interface_shared.py", line 38, in _publish_output_raw
    self._publish(rec)
  File "/opt/anaconda3/envs/myenv/lib/python3.11/site-packages/wandb/sdk/interface/interface_sock.py", line 39, in _publish
    self._sock_client.send_record_publish(record)
  File "/opt/anaconda3/envs/myenv/lib/python3.11/site-packages/wandb/sdk/lib/sock_client.py", line 174, in send_record_publish
    self.send_server_request(server_req)
  File "/opt/anaconda3/envs/myenv/lib/python3.11/site-packages/wandb/sdk/lib/sock_client.py", line 154, in send_server_request
    self._send_message(msg)
  File "/opt/anaconda3/envs/myenv/lib/python3.11/site-packages/wandb/sdk/lib/sock_client.py", line 151, in _send_message
    self._sendall_with_error_handle(header + data)
  File "/opt/anaconda3/envs/myenv/lib/python3.11/site-packages/wandb/sdk/lib/sock_client.py", line 130, in _sendall_with_error_handle
    sent = self._sock.send(data)
           ^^^^^^^^^^^^^^^^^^^^^
BrokenPipeError: [Errno 32] Broken pipe
2025-07-16 11:32:13,146 ERROR   MainThread:59013 [redirect.py:_on_write():664] [no run ID] error in stderr callback
Traceback (most recent call last):
  File "/opt/anaconda3/envs/myenv/lib/python3.11/site-packages/wandb/sdk/lib/redirect.py", line 662, in _on_write
    cb(written_data)
  File "/opt/anaconda3/envs/myenv/lib/python3.11/site-packages/wandb/sdk/wandb_run.py", line 2380, in <lambda>
    lambda data: self._console_raw_callback("stderr", data),
                 ^^^^^^^^^^^^^^^^^^^^^^^^^^^^^^^^^^^^^^^^^^
  File "/opt/anaconda3/envs/myenv/lib/python3.11/site-packages/wandb/sdk/wandb_run.py", line 391, in wrapper
    return func(self, *args, **kwargs)
           ^^^^^^^^^^^^^^^^^^^^^^^^^^^
  File "/opt/anaconda3/envs/myenv/lib/python3.11/site-packages/wandb/sdk/wandb_run.py", line 449, in wrapper_fn
    return func(self, *args, **kwargs)
           ^^^^^^^^^^^^^^^^^^^^^^^^^^^
  File "/opt/anaconda3/envs/myenv/lib/python3.11/site-packages/wandb/sdk/wandb_run.py", line 1561, in _console_raw_callback
    self._backend.interface.publish_output_raw(name, data)
  File "/opt/anaconda3/envs/myenv/lib/python3.11/site-packages/wandb/sdk/interface/interface.py", line 772, in publish_output_raw
    self._publish_output_raw(o)
  File "/opt/anaconda3/envs/myenv/lib/python3.11/site-packages/wandb/sdk/interface/interface_shared.py", line 38, in _publish_output_raw
    self._publish(rec)
  File "/opt/anaconda3/envs/myenv/lib/python3.11/site-packages/wandb/sdk/interface/interface_sock.py", line 39, in _publish
    self._sock_client.send_record_publish(record)
  File "/opt/anaconda3/envs/myenv/lib/python3.11/site-packages/wandb/sdk/lib/sock_client.py", line 174, in send_record_publish
    self.send_server_request(server_req)
  File "/opt/anaconda3/envs/myenv/lib/python3.11/site-packages/wandb/sdk/lib/sock_client.py", line 154, in send_server_request
    self._send_message(msg)
  File "/opt/anaconda3/envs/myenv/lib/python3.11/site-packages/wandb/sdk/lib/sock_client.py", line 151, in _send_message
    self._sendall_with_error_handle(header + data)
  File "/opt/anaconda3/envs/myenv/lib/python3.11/site-packages/wandb/sdk/lib/sock_client.py", line 130, in _sendall_with_error_handle
    sent = self._sock.send(data)
           ^^^^^^^^^^^^^^^^^^^^^
BrokenPipeError: [Errno 32] Broken pipe
2025-07-16 11:32:13,146 ERROR   MainThread:59013 [redirect.py:_on_write():664] [no run ID] error in stderr callback
Traceback (most recent call last):
  File "/opt/anaconda3/envs/myenv/lib/python3.11/site-packages/wandb/sdk/lib/redirect.py", line 662, in _on_write
    cb(written_data)
  File "/opt/anaconda3/envs/myenv/lib/python3.11/site-packages/wandb/sdk/wandb_run.py", line 2380, in <lambda>
    lambda data: self._console_raw_callback("stderr", data),
                 ^^^^^^^^^^^^^^^^^^^^^^^^^^^^^^^^^^^^^^^^^^
  File "/opt/anaconda3/envs/myenv/lib/python3.11/site-packages/wandb/sdk/wandb_run.py", line 391, in wrapper
    return func(self, *args, **kwargs)
           ^^^^^^^^^^^^^^^^^^^^^^^^^^^
  File "/opt/anaconda3/envs/myenv/lib/python3.11/site-packages/wandb/sdk/wandb_run.py", line 449, in wrapper_fn
    return func(self, *args, **kwargs)
           ^^^^^^^^^^^^^^^^^^^^^^^^^^^
  File "/opt/anaconda3/envs/myenv/lib/python3.11/site-packages/wandb/sdk/wandb_run.py", line 1561, in _console_raw_callback
    self._backend.interface.publish_output_raw(name, data)
  File "/opt/anaconda3/envs/myenv/lib/python3.11/site-packages/wandb/sdk/interface/interface.py", line 772, in publish_output_raw
    self._publish_output_raw(o)
  File "/opt/anaconda3/envs/myenv/lib/python3.11/site-packages/wandb/sdk/interface/interface_shared.py", line 38, in _publish_output_raw
    self._publish(rec)
  File "/opt/anaconda3/envs/myenv/lib/python3.11/site-packages/wandb/sdk/interface/interface_sock.py", line 39, in _publish
    self._sock_client.send_record_publish(record)
  File "/opt/anaconda3/envs/myenv/lib/python3.11/site-packages/wandb/sdk/lib/sock_client.py", line 174, in send_record_publish
    self.send_server_request(server_req)
  File "/opt/anaconda3/envs/myenv/lib/python3.11/site-packages/wandb/sdk/lib/sock_client.py", line 154, in send_server_request
    self._send_message(msg)
  File "/opt/anaconda3/envs/myenv/lib/python3.11/site-packages/wandb/sdk/lib/sock_client.py", line 151, in _send_message
    self._sendall_with_error_handle(header + data)
  File "/opt/anaconda3/envs/myenv/lib/python3.11/site-packages/wandb/sdk/lib/sock_client.py", line 130, in _sendall_with_error_handle
    sent = self._sock.send(data)
           ^^^^^^^^^^^^^^^^^^^^^
BrokenPipeError: [Errno 32] Broken pipe
2025-07-16 11:32:13,147 ERROR   MainThread:59013 [redirect.py:_on_write():664] [no run ID] error in stderr callback
Traceback (most recent call last):
  File "/opt/anaconda3/envs/myenv/lib/python3.11/site-packages/wandb/sdk/lib/redirect.py", line 662, in _on_write
    cb(written_data)
  File "/opt/anaconda3/envs/myenv/lib/python3.11/site-packages/wandb/sdk/wandb_run.py", line 2380, in <lambda>
    lambda data: self._console_raw_callback("stderr", data),
                 ^^^^^^^^^^^^^^^^^^^^^^^^^^^^^^^^^^^^^^^^^^
  File "/opt/anaconda3/envs/myenv/lib/python3.11/site-packages/wandb/sdk/wandb_run.py", line 391, in wrapper
    return func(self, *args, **kwargs)
           ^^^^^^^^^^^^^^^^^^^^^^^^^^^
  File "/opt/anaconda3/envs/myenv/lib/python3.11/site-packages/wandb/sdk/wandb_run.py", line 449, in wrapper_fn
    return func(self, *args, **kwargs)
           ^^^^^^^^^^^^^^^^^^^^^^^^^^^
  File "/opt/anaconda3/envs/myenv/lib/python3.11/site-packages/wandb/sdk/wandb_run.py", line 1561, in _console_raw_callback
    self._backend.interface.publish_output_raw(name, data)
  File "/opt/anaconda3/envs/myenv/lib/python3.11/site-packages/wandb/sdk/interface/interface.py", line 772, in publish_output_raw
    self._publish_output_raw(o)
  File "/opt/anaconda3/envs/myenv/lib/python3.11/site-packages/wandb/sdk/interface/interface_shared.py", line 38, in _publish_output_raw
    self._publish(rec)
  File "/opt/anaconda3/envs/myenv/lib/python3.11/site-packages/wandb/sdk/interface/interface_sock.py", line 39, in _publish
    self._sock_client.send_record_publish(record)
  File "/opt/anaconda3/envs/myenv/lib/python3.11/site-packages/wandb/sdk/lib/sock_client.py", line 174, in send_record_publish
    self.send_server_request(server_req)
  File "/opt/anaconda3/envs/myenv/lib/python3.11/site-packages/wandb/sdk/lib/sock_client.py", line 154, in send_server_request
    self._send_message(msg)
  File "/opt/anaconda3/envs/myenv/lib/python3.11/site-packages/wandb/sdk/lib/sock_client.py", line 151, in _send_message
    self._sendall_with_error_handle(header + data)
  File "/opt/anaconda3/envs/myenv/lib/python3.11/site-packages/wandb/sdk/lib/sock_client.py", line 130, in _sendall_with_error_handle
    sent = self._sock.send(data)
           ^^^^^^^^^^^^^^^^^^^^^
BrokenPipeError: [Errno 32] Broken pipe
2025-07-16 11:32:13,147 ERROR   MainThread:59013 [redirect.py:_on_write():664] [no run ID] error in stderr callback
Traceback (most recent call last):
  File "/opt/anaconda3/envs/myenv/lib/python3.11/site-packages/wandb/sdk/lib/redirect.py", line 662, in _on_write
    cb(written_data)
  File "/opt/anaconda3/envs/myenv/lib/python3.11/site-packages/wandb/sdk/wandb_run.py", line 2380, in <lambda>
    lambda data: self._console_raw_callback("stderr", data),
                 ^^^^^^^^^^^^^^^^^^^^^^^^^^^^^^^^^^^^^^^^^^
  File "/opt/anaconda3/envs/myenv/lib/python3.11/site-packages/wandb/sdk/wandb_run.py", line 391, in wrapper
    return func(self, *args, **kwargs)
           ^^^^^^^^^^^^^^^^^^^^^^^^^^^
  File "/opt/anaconda3/envs/myenv/lib/python3.11/site-packages/wandb/sdk/wandb_run.py", line 449, in wrapper_fn
    return func(self, *args, **kwargs)
           ^^^^^^^^^^^^^^^^^^^^^^^^^^^
  File "/opt/anaconda3/envs/myenv/lib/python3.11/site-packages/wandb/sdk/wandb_run.py", line 1561, in _console_raw_callback
    self._backend.interface.publish_output_raw(name, data)
  File "/opt/anaconda3/envs/myenv/lib/python3.11/site-packages/wandb/sdk/interface/interface.py", line 772, in publish_output_raw
    self._publish_output_raw(o)
  File "/opt/anaconda3/envs/myenv/lib/python3.11/site-packages/wandb/sdk/interface/interface_shared.py", line 38, in _publish_output_raw
    self._publish(rec)
  File "/opt/anaconda3/envs/myenv/lib/python3.11/site-packages/wandb/sdk/interface/interface_sock.py", line 39, in _publish
    self._sock_client.send_record_publish(record)
  File "/opt/anaconda3/envs/myenv/lib/python3.11/site-packages/wandb/sdk/lib/sock_client.py", line 174, in send_record_publish
    self.send_server_request(server_req)
  File "/opt/anaconda3/envs/myenv/lib/python3.11/site-packages/wandb/sdk/lib/sock_client.py", line 154, in send_server_request
    self._send_message(msg)
  File "/opt/anaconda3/envs/myenv/lib/python3.11/site-packages/wandb/sdk/lib/sock_client.py", line 151, in _send_message
    self._sendall_with_error_handle(header + data)
  File "/opt/anaconda3/envs/myenv/lib/python3.11/site-packages/wandb/sdk/lib/sock_client.py", line 130, in _sendall_with_error_handle
    sent = self._sock.send(data)
           ^^^^^^^^^^^^^^^^^^^^^
BrokenPipeError: [Errno 32] Broken pipe
2025-07-16 11:32:13,147 ERROR   MainThread:59013 [redirect.py:_on_write():664] [no run ID] error in stderr callback
Traceback (most recent call last):
  File "/opt/anaconda3/envs/myenv/lib/python3.11/site-packages/wandb/sdk/lib/redirect.py", line 662, in _on_write
    cb(written_data)
  File "/opt/anaconda3/envs/myenv/lib/python3.11/site-packages/wandb/sdk/wandb_run.py", line 2380, in <lambda>
    lambda data: self._console_raw_callback("stderr", data),
                 ^^^^^^^^^^^^^^^^^^^^^^^^^^^^^^^^^^^^^^^^^^
  File "/opt/anaconda3/envs/myenv/lib/python3.11/site-packages/wandb/sdk/wandb_run.py", line 391, in wrapper
    return func(self, *args, **kwargs)
           ^^^^^^^^^^^^^^^^^^^^^^^^^^^
  File "/opt/anaconda3/envs/myenv/lib/python3.11/site-packages/wandb/sdk/wandb_run.py", line 449, in wrapper_fn
    return func(self, *args, **kwargs)
           ^^^^^^^^^^^^^^^^^^^^^^^^^^^
  File "/opt/anaconda3/envs/myenv/lib/python3.11/site-packages/wandb/sdk/wandb_run.py", line 1561, in _console_raw_callback
    self._backend.interface.publish_output_raw(name, data)
  File "/opt/anaconda3/envs/myenv/lib/python3.11/site-packages/wandb/sdk/interface/interface.py", line 772, in publish_output_raw
    self._publish_output_raw(o)
  File "/opt/anaconda3/envs/myenv/lib/python3.11/site-packages/wandb/sdk/interface/interface_shared.py", line 38, in _publish_output_raw
    self._publish(rec)
  File "/opt/anaconda3/envs/myenv/lib/python3.11/site-packages/wandb/sdk/interface/interface_sock.py", line 39, in _publish
    self._sock_client.send_record_publish(record)
  File "/opt/anaconda3/envs/myenv/lib/python3.11/site-packages/wandb/sdk/lib/sock_client.py", line 174, in send_record_publish
    self.send_server_request(server_req)
  File "/opt/anaconda3/envs/myenv/lib/python3.11/site-packages/wandb/sdk/lib/sock_client.py", line 154, in send_server_request
    self._send_message(msg)
  File "/opt/anaconda3/envs/myenv/lib/python3.11/site-packages/wandb/sdk/lib/sock_client.py", line 151, in _send_message
    self._sendall_with_error_handle(header + data)
  File "/opt/anaconda3/envs/myenv/lib/python3.11/site-packages/wandb/sdk/lib/sock_client.py", line 130, in _sendall_with_error_handle
    sent = self._sock.send(data)
           ^^^^^^^^^^^^^^^^^^^^^
BrokenPipeError: [Errno 32] Broken pipe
2025-07-16 11:32:13,148 ERROR   MainThread:59013 [redirect.py:_on_write():664] [no run ID] error in stderr callback
Traceback (most recent call last):
  File "/opt/anaconda3/envs/myenv/lib/python3.11/site-packages/wandb/sdk/lib/redirect.py", line 662, in _on_write
    cb(written_data)
  File "/opt/anaconda3/envs/myenv/lib/python3.11/site-packages/wandb/sdk/wandb_run.py", line 2380, in <lambda>
    lambda data: self._console_raw_callback("stderr", data),
                 ^^^^^^^^^^^^^^^^^^^^^^^^^^^^^^^^^^^^^^^^^^
  File "/opt/anaconda3/envs/myenv/lib/python3.11/site-packages/wandb/sdk/wandb_run.py", line 391, in wrapper
    return func(self, *args, **kwargs)
           ^^^^^^^^^^^^^^^^^^^^^^^^^^^
  File "/opt/anaconda3/envs/myenv/lib/python3.11/site-packages/wandb/sdk/wandb_run.py", line 449, in wrapper_fn
    return func(self, *args, **kwargs)
           ^^^^^^^^^^^^^^^^^^^^^^^^^^^
  File "/opt/anaconda3/envs/myenv/lib/python3.11/site-packages/wandb/sdk/wandb_run.py", line 1561, in _console_raw_callback
    self._backend.interface.publish_output_raw(name, data)
  File "/opt/anaconda3/envs/myenv/lib/python3.11/site-packages/wandb/sdk/interface/interface.py", line 772, in publish_output_raw
    self._publish_output_raw(o)
  File "/opt/anaconda3/envs/myenv/lib/python3.11/site-packages/wandb/sdk/interface/interface_shared.py", line 38, in _publish_output_raw
    self._publish(rec)
  File "/opt/anaconda3/envs/myenv/lib/python3.11/site-packages/wandb/sdk/interface/interface_sock.py", line 39, in _publish
    self._sock_client.send_record_publish(record)
  File "/opt/anaconda3/envs/myenv/lib/python3.11/site-packages/wandb/sdk/lib/sock_client.py", line 174, in send_record_publish
    self.send_server_request(server_req)
  File "/opt/anaconda3/envs/myenv/lib/python3.11/site-packages/wandb/sdk/lib/sock_client.py", line 154, in send_server_request
    self._send_message(msg)
  File "/opt/anaconda3/envs/myenv/lib/python3.11/site-packages/wandb/sdk/lib/sock_client.py", line 151, in _send_message
    self._sendall_with_error_handle(header + data)
  File "/opt/anaconda3/envs/myenv/lib/python3.11/site-packages/wandb/sdk/lib/sock_client.py", line 130, in _sendall_with_error_handle
    sent = self._sock.send(data)
           ^^^^^^^^^^^^^^^^^^^^^
BrokenPipeError: [Errno 32] Broken pipe
2025-07-16 11:32:13,148 ERROR   MainThread:59013 [redirect.py:_on_write():664] [no run ID] error in stderr callback
Traceback (most recent call last):
  File "/opt/anaconda3/envs/myenv/lib/python3.11/site-packages/wandb/sdk/lib/redirect.py", line 662, in _on_write
    cb(written_data)
  File "/opt/anaconda3/envs/myenv/lib/python3.11/site-packages/wandb/sdk/wandb_run.py", line 2380, in <lambda>
    lambda data: self._console_raw_callback("stderr", data),
                 ^^^^^^^^^^^^^^^^^^^^^^^^^^^^^^^^^^^^^^^^^^
  File "/opt/anaconda3/envs/myenv/lib/python3.11/site-packages/wandb/sdk/wandb_run.py", line 391, in wrapper
    return func(self, *args, **kwargs)
           ^^^^^^^^^^^^^^^^^^^^^^^^^^^
  File "/opt/anaconda3/envs/myenv/lib/python3.11/site-packages/wandb/sdk/wandb_run.py", line 449, in wrapper_fn
    return func(self, *args, **kwargs)
           ^^^^^^^^^^^^^^^^^^^^^^^^^^^
  File "/opt/anaconda3/envs/myenv/lib/python3.11/site-packages/wandb/sdk/wandb_run.py", line 1561, in _console_raw_callback
    self._backend.interface.publish_output_raw(name, data)
  File "/opt/anaconda3/envs/myenv/lib/python3.11/site-packages/wandb/sdk/interface/interface.py", line 772, in publish_output_raw
    self._publish_output_raw(o)
  File "/opt/anaconda3/envs/myenv/lib/python3.11/site-packages/wandb/sdk/interface/interface_shared.py", line 38, in _publish_output_raw
    self._publish(rec)
  File "/opt/anaconda3/envs/myenv/lib/python3.11/site-packages/wandb/sdk/interface/interface_sock.py", line 39, in _publish
    self._sock_client.send_record_publish(record)
  File "/opt/anaconda3/envs/myenv/lib/python3.11/site-packages/wandb/sdk/lib/sock_client.py", line 174, in send_record_publish
    self.send_server_request(server_req)
  File "/opt/anaconda3/envs/myenv/lib/python3.11/site-packages/wandb/sdk/lib/sock_client.py", line 154, in send_server_request
    self._send_message(msg)
  File "/opt/anaconda3/envs/myenv/lib/python3.11/site-packages/wandb/sdk/lib/sock_client.py", line 151, in _send_message
    self._sendall_with_error_handle(header + data)
  File "/opt/anaconda3/envs/myenv/lib/python3.11/site-packages/wandb/sdk/lib/sock_client.py", line 130, in _sendall_with_error_handle
    sent = self._sock.send(data)
           ^^^^^^^^^^^^^^^^^^^^^
BrokenPipeError: [Errno 32] Broken pipe
2025-07-16 11:32:13,149 ERROR   MainThread:59013 [redirect.py:_on_write():664] [no run ID] error in stderr callback
Traceback (most recent call last):
  File "/opt/anaconda3/envs/myenv/lib/python3.11/site-packages/wandb/sdk/lib/redirect.py", line 662, in _on_write
    cb(written_data)
  File "/opt/anaconda3/envs/myenv/lib/python3.11/site-packages/wandb/sdk/wandb_run.py", line 2380, in <lambda>
    lambda data: self._console_raw_callback("stderr", data),
                 ^^^^^^^^^^^^^^^^^^^^^^^^^^^^^^^^^^^^^^^^^^
  File "/opt/anaconda3/envs/myenv/lib/python3.11/site-packages/wandb/sdk/wandb_run.py", line 391, in wrapper
    return func(self, *args, **kwargs)
           ^^^^^^^^^^^^^^^^^^^^^^^^^^^
  File "/opt/anaconda3/envs/myenv/lib/python3.11/site-packages/wandb/sdk/wandb_run.py", line 449, in wrapper_fn
    return func(self, *args, **kwargs)
           ^^^^^^^^^^^^^^^^^^^^^^^^^^^
  File "/opt/anaconda3/envs/myenv/lib/python3.11/site-packages/wandb/sdk/wandb_run.py", line 1561, in _console_raw_callback
    self._backend.interface.publish_output_raw(name, data)
  File "/opt/anaconda3/envs/myenv/lib/python3.11/site-packages/wandb/sdk/interface/interface.py", line 772, in publish_output_raw
    self._publish_output_raw(o)
  File "/opt/anaconda3/envs/myenv/lib/python3.11/site-packages/wandb/sdk/interface/interface_shared.py", line 38, in _publish_output_raw
    self._publish(rec)
  File "/opt/anaconda3/envs/myenv/lib/python3.11/site-packages/wandb/sdk/interface/interface_sock.py", line 39, in _publish
    self._sock_client.send_record_publish(record)
  File "/opt/anaconda3/envs/myenv/lib/python3.11/site-packages/wandb/sdk/lib/sock_client.py", line 174, in send_record_publish
    self.send_server_request(server_req)
  File "/opt/anaconda3/envs/myenv/lib/python3.11/site-packages/wandb/sdk/lib/sock_client.py", line 154, in send_server_request
    self._send_message(msg)
  File "/opt/anaconda3/envs/myenv/lib/python3.11/site-packages/wandb/sdk/lib/sock_client.py", line 151, in _send_message
    self._sendall_with_error_handle(header + data)
  File "/opt/anaconda3/envs/myenv/lib/python3.11/site-packages/wandb/sdk/lib/sock_client.py", line 130, in _sendall_with_error_handle
    sent = self._sock.send(data)
           ^^^^^^^^^^^^^^^^^^^^^
BrokenPipeError: [Errno 32] Broken pipe
2025-07-16 11:32:13,150 ERROR   MainThread:59013 [redirect.py:_on_write():664] [no run ID] error in stderr callback
Traceback (most recent call last):
  File "/opt/anaconda3/envs/myenv/lib/python3.11/site-packages/wandb/sdk/lib/redirect.py", line 662, in _on_write
    cb(written_data)
  File "/opt/anaconda3/envs/myenv/lib/python3.11/site-packages/wandb/sdk/wandb_run.py", line 2380, in <lambda>
    lambda data: self._console_raw_callback("stderr", data),
                 ^^^^^^^^^^^^^^^^^^^^^^^^^^^^^^^^^^^^^^^^^^
  File "/opt/anaconda3/envs/myenv/lib/python3.11/site-packages/wandb/sdk/wandb_run.py", line 391, in wrapper
    return func(self, *args, **kwargs)
           ^^^^^^^^^^^^^^^^^^^^^^^^^^^
  File "/opt/anaconda3/envs/myenv/lib/python3.11/site-packages/wandb/sdk/wandb_run.py", line 449, in wrapper_fn
    return func(self, *args, **kwargs)
           ^^^^^^^^^^^^^^^^^^^^^^^^^^^
  File "/opt/anaconda3/envs/myenv/lib/python3.11/site-packages/wandb/sdk/wandb_run.py", line 1561, in _console_raw_callback
    self._backend.interface.publish_output_raw(name, data)
  File "/opt/anaconda3/envs/myenv/lib/python3.11/site-packages/wandb/sdk/interface/interface.py", line 772, in publish_output_raw
    self._publish_output_raw(o)
  File "/opt/anaconda3/envs/myenv/lib/python3.11/site-packages/wandb/sdk/interface/interface_shared.py", line 38, in _publish_output_raw
    self._publish(rec)
  File "/opt/anaconda3/envs/myenv/lib/python3.11/site-packages/wandb/sdk/interface/interface_sock.py", line 39, in _publish
    self._sock_client.send_record_publish(record)
  File "/opt/anaconda3/envs/myenv/lib/python3.11/site-packages/wandb/sdk/lib/sock_client.py", line 174, in send_record_publish
    self.send_server_request(server_req)
  File "/opt/anaconda3/envs/myenv/lib/python3.11/site-packages/wandb/sdk/lib/sock_client.py", line 154, in send_server_request
    self._send_message(msg)
  File "/opt/anaconda3/envs/myenv/lib/python3.11/site-packages/wandb/sdk/lib/sock_client.py", line 151, in _send_message
    self._sendall_with_error_handle(header + data)
  File "/opt/anaconda3/envs/myenv/lib/python3.11/site-packages/wandb/sdk/lib/sock_client.py", line 130, in _sendall_with_error_handle
    sent = self._sock.send(data)
           ^^^^^^^^^^^^^^^^^^^^^
BrokenPipeError: [Errno 32] Broken pipe
2025-07-16 11:32:13,150 ERROR   MainThread:59013 [redirect.py:_on_write():664] [no run ID] error in stderr callback
Traceback (most recent call last):
  File "/opt/anaconda3/envs/myenv/lib/python3.11/site-packages/wandb/sdk/lib/redirect.py", line 662, in _on_write
    cb(written_data)
  File "/opt/anaconda3/envs/myenv/lib/python3.11/site-packages/wandb/sdk/wandb_run.py", line 2380, in <lambda>
    lambda data: self._console_raw_callback("stderr", data),
                 ^^^^^^^^^^^^^^^^^^^^^^^^^^^^^^^^^^^^^^^^^^
  File "/opt/anaconda3/envs/myenv/lib/python3.11/site-packages/wandb/sdk/wandb_run.py", line 391, in wrapper
    return func(self, *args, **kwargs)
           ^^^^^^^^^^^^^^^^^^^^^^^^^^^
  File "/opt/anaconda3/envs/myenv/lib/python3.11/site-packages/wandb/sdk/wandb_run.py", line 449, in wrapper_fn
    return func(self, *args, **kwargs)
           ^^^^^^^^^^^^^^^^^^^^^^^^^^^
  File "/opt/anaconda3/envs/myenv/lib/python3.11/site-packages/wandb/sdk/wandb_run.py", line 1561, in _console_raw_callback
    self._backend.interface.publish_output_raw(name, data)
  File "/opt/anaconda3/envs/myenv/lib/python3.11/site-packages/wandb/sdk/interface/interface.py", line 772, in publish_output_raw
    self._publish_output_raw(o)
  File "/opt/anaconda3/envs/myenv/lib/python3.11/site-packages/wandb/sdk/interface/interface_shared.py", line 38, in _publish_output_raw
    self._publish(rec)
  File "/opt/anaconda3/envs/myenv/lib/python3.11/site-packages/wandb/sdk/interface/interface_sock.py", line 39, in _publish
    self._sock_client.send_record_publish(record)
  File "/opt/anaconda3/envs/myenv/lib/python3.11/site-packages/wandb/sdk/lib/sock_client.py", line 174, in send_record_publish
    self.send_server_request(server_req)
  File "/opt/anaconda3/envs/myenv/lib/python3.11/site-packages/wandb/sdk/lib/sock_client.py", line 154, in send_server_request
    self._send_message(msg)
  File "/opt/anaconda3/envs/myenv/lib/python3.11/site-packages/wandb/sdk/lib/sock_client.py", line 151, in _send_message
    self._sendall_with_error_handle(header + data)
  File "/opt/anaconda3/envs/myenv/lib/python3.11/site-packages/wandb/sdk/lib/sock_client.py", line 130, in _sendall_with_error_handle
    sent = self._sock.send(data)
           ^^^^^^^^^^^^^^^^^^^^^
BrokenPipeError: [Errno 32] Broken pipe
2025-07-16 11:32:13,150 ERROR   MainThread:59013 [redirect.py:_on_write():664] [no run ID] error in stderr callback
Traceback (most recent call last):
  File "/opt/anaconda3/envs/myenv/lib/python3.11/site-packages/wandb/sdk/lib/redirect.py", line 662, in _on_write
    cb(written_data)
  File "/opt/anaconda3/envs/myenv/lib/python3.11/site-packages/wandb/sdk/wandb_run.py", line 2380, in <lambda>
    lambda data: self._console_raw_callback("stderr", data),
                 ^^^^^^^^^^^^^^^^^^^^^^^^^^^^^^^^^^^^^^^^^^
  File "/opt/anaconda3/envs/myenv/lib/python3.11/site-packages/wandb/sdk/wandb_run.py", line 391, in wrapper
    return func(self, *args, **kwargs)
           ^^^^^^^^^^^^^^^^^^^^^^^^^^^
  File "/opt/anaconda3/envs/myenv/lib/python3.11/site-packages/wandb/sdk/wandb_run.py", line 449, in wrapper_fn
    return func(self, *args, **kwargs)
           ^^^^^^^^^^^^^^^^^^^^^^^^^^^
  File "/opt/anaconda3/envs/myenv/lib/python3.11/site-packages/wandb/sdk/wandb_run.py", line 1561, in _console_raw_callback
    self._backend.interface.publish_output_raw(name, data)
  File "/opt/anaconda3/envs/myenv/lib/python3.11/site-packages/wandb/sdk/interface/interface.py", line 772, in publish_output_raw
    self._publish_output_raw(o)
  File "/opt/anaconda3/envs/myenv/lib/python3.11/site-packages/wandb/sdk/interface/interface_shared.py", line 38, in _publish_output_raw
    self._publish(rec)
  File "/opt/anaconda3/envs/myenv/lib/python3.11/site-packages/wandb/sdk/interface/interface_sock.py", line 39, in _publish
    self._sock_client.send_record_publish(record)
  File "/opt/anaconda3/envs/myenv/lib/python3.11/site-packages/wandb/sdk/lib/sock_client.py", line 174, in send_record_publish
    self.send_server_request(server_req)
  File "/opt/anaconda3/envs/myenv/lib/python3.11/site-packages/wandb/sdk/lib/sock_client.py", line 154, in send_server_request
    self._send_message(msg)
  File "/opt/anaconda3/envs/myenv/lib/python3.11/site-packages/wandb/sdk/lib/sock_client.py", line 151, in _send_message
    self._sendall_with_error_handle(header + data)
  File "/opt/anaconda3/envs/myenv/lib/python3.11/site-packages/wandb/sdk/lib/sock_client.py", line 130, in _sendall_with_error_handle
    sent = self._sock.send(data)
           ^^^^^^^^^^^^^^^^^^^^^
BrokenPipeError: [Errno 32] Broken pipe
2025-07-16 11:32:13,151 ERROR   MainThread:59013 [redirect.py:_on_write():664] [no run ID] error in stderr callback
Traceback (most recent call last):
  File "/opt/anaconda3/envs/myenv/lib/python3.11/site-packages/wandb/sdk/lib/redirect.py", line 662, in _on_write
    cb(written_data)
  File "/opt/anaconda3/envs/myenv/lib/python3.11/site-packages/wandb/sdk/wandb_run.py", line 2380, in <lambda>
    lambda data: self._console_raw_callback("stderr", data),
                 ^^^^^^^^^^^^^^^^^^^^^^^^^^^^^^^^^^^^^^^^^^
  File "/opt/anaconda3/envs/myenv/lib/python3.11/site-packages/wandb/sdk/wandb_run.py", line 391, in wrapper
    return func(self, *args, **kwargs)
           ^^^^^^^^^^^^^^^^^^^^^^^^^^^
  File "/opt/anaconda3/envs/myenv/lib/python3.11/site-packages/wandb/sdk/wandb_run.py", line 449, in wrapper_fn
    return func(self, *args, **kwargs)
           ^^^^^^^^^^^^^^^^^^^^^^^^^^^
  File "/opt/anaconda3/envs/myenv/lib/python3.11/site-packages/wandb/sdk/wandb_run.py", line 1561, in _console_raw_callback
    self._backend.interface.publish_output_raw(name, data)
  File "/opt/anaconda3/envs/myenv/lib/python3.11/site-packages/wandb/sdk/interface/interface.py", line 772, in publish_output_raw
    self._publish_output_raw(o)
  File "/opt/anaconda3/envs/myenv/lib/python3.11/site-packages/wandb/sdk/interface/interface_shared.py", line 38, in _publish_output_raw
    self._publish(rec)
  File "/opt/anaconda3/envs/myenv/lib/python3.11/site-packages/wandb/sdk/interface/interface_sock.py", line 39, in _publish
    self._sock_client.send_record_publish(record)
  File "/opt/anaconda3/envs/myenv/lib/python3.11/site-packages/wandb/sdk/lib/sock_client.py", line 174, in send_record_publish
    self.send_server_request(server_req)
  File "/opt/anaconda3/envs/myenv/lib/python3.11/site-packages/wandb/sdk/lib/sock_client.py", line 154, in send_server_request
    self._send_message(msg)
  File "/opt/anaconda3/envs/myenv/lib/python3.11/site-packages/wandb/sdk/lib/sock_client.py", line 151, in _send_message
    self._sendall_with_error_handle(header + data)
  File "/opt/anaconda3/envs/myenv/lib/python3.11/site-packages/wandb/sdk/lib/sock_client.py", line 130, in _sendall_with_error_handle
    sent = self._sock.send(data)
           ^^^^^^^^^^^^^^^^^^^^^
BrokenPipeError: [Errno 32] Broken pipe
2025-07-16 11:32:13,151 ERROR   MainThread:59013 [redirect.py:_on_write():664] [no run ID] error in stderr callback
Traceback (most recent call last):
  File "/opt/anaconda3/envs/myenv/lib/python3.11/site-packages/wandb/sdk/lib/redirect.py", line 662, in _on_write
    cb(written_data)
  File "/opt/anaconda3/envs/myenv/lib/python3.11/site-packages/wandb/sdk/wandb_run.py", line 2380, in <lambda>
    lambda data: self._console_raw_callback("stderr", data),
                 ^^^^^^^^^^^^^^^^^^^^^^^^^^^^^^^^^^^^^^^^^^
  File "/opt/anaconda3/envs/myenv/lib/python3.11/site-packages/wandb/sdk/wandb_run.py", line 391, in wrapper
    return func(self, *args, **kwargs)
           ^^^^^^^^^^^^^^^^^^^^^^^^^^^
  File "/opt/anaconda3/envs/myenv/lib/python3.11/site-packages/wandb/sdk/wandb_run.py", line 449, in wrapper_fn
    return func(self, *args, **kwargs)
           ^^^^^^^^^^^^^^^^^^^^^^^^^^^
  File "/opt/anaconda3/envs/myenv/lib/python3.11/site-packages/wandb/sdk/wandb_run.py", line 1561, in _console_raw_callback
    self._backend.interface.publish_output_raw(name, data)
  File "/opt/anaconda3/envs/myenv/lib/python3.11/site-packages/wandb/sdk/interface/interface.py", line 772, in publish_output_raw
    self._publish_output_raw(o)
  File "/opt/anaconda3/envs/myenv/lib/python3.11/site-packages/wandb/sdk/interface/interface_shared.py", line 38, in _publish_output_raw
    self._publish(rec)
  File "/opt/anaconda3/envs/myenv/lib/python3.11/site-packages/wandb/sdk/interface/interface_sock.py", line 39, in _publish
    self._sock_client.send_record_publish(record)
  File "/opt/anaconda3/envs/myenv/lib/python3.11/site-packages/wandb/sdk/lib/sock_client.py", line 174, in send_record_publish
    self.send_server_request(server_req)
  File "/opt/anaconda3/envs/myenv/lib/python3.11/site-packages/wandb/sdk/lib/sock_client.py", line 154, in send_server_request
    self._send_message(msg)
  File "/opt/anaconda3/envs/myenv/lib/python3.11/site-packages/wandb/sdk/lib/sock_client.py", line 151, in _send_message
    self._sendall_with_error_handle(header + data)
  File "/opt/anaconda3/envs/myenv/lib/python3.11/site-packages/wandb/sdk/lib/sock_client.py", line 130, in _sendall_with_error_handle
    sent = self._sock.send(data)
           ^^^^^^^^^^^^^^^^^^^^^
BrokenPipeError: [Errno 32] Broken pipe
2025-07-16 11:32:13,152 ERROR   MainThread:59013 [redirect.py:_on_write():664] [no run ID] error in stderr callback
Traceback (most recent call last):
  File "/opt/anaconda3/envs/myenv/lib/python3.11/site-packages/wandb/sdk/lib/redirect.py", line 662, in _on_write
    cb(written_data)
  File "/opt/anaconda3/envs/myenv/lib/python3.11/site-packages/wandb/sdk/wandb_run.py", line 2380, in <lambda>
    lambda data: self._console_raw_callback("stderr", data),
                 ^^^^^^^^^^^^^^^^^^^^^^^^^^^^^^^^^^^^^^^^^^
  File "/opt/anaconda3/envs/myenv/lib/python3.11/site-packages/wandb/sdk/wandb_run.py", line 391, in wrapper
    return func(self, *args, **kwargs)
           ^^^^^^^^^^^^^^^^^^^^^^^^^^^
  File "/opt/anaconda3/envs/myenv/lib/python3.11/site-packages/wandb/sdk/wandb_run.py", line 449, in wrapper_fn
    return func(self, *args, **kwargs)
           ^^^^^^^^^^^^^^^^^^^^^^^^^^^
  File "/opt/anaconda3/envs/myenv/lib/python3.11/site-packages/wandb/sdk/wandb_run.py", line 1561, in _console_raw_callback
    self._backend.interface.publish_output_raw(name, data)
  File "/opt/anaconda3/envs/myenv/lib/python3.11/site-packages/wandb/sdk/interface/interface.py", line 772, in publish_output_raw
    self._publish_output_raw(o)
  File "/opt/anaconda3/envs/myenv/lib/python3.11/site-packages/wandb/sdk/interface/interface_shared.py", line 38, in _publish_output_raw
    self._publish(rec)
  File "/opt/anaconda3/envs/myenv/lib/python3.11/site-packages/wandb/sdk/interface/interface_sock.py", line 39, in _publish
    self._sock_client.send_record_publish(record)
  File "/opt/anaconda3/envs/myenv/lib/python3.11/site-packages/wandb/sdk/lib/sock_client.py", line 174, in send_record_publish
    self.send_server_request(server_req)
  File "/opt/anaconda3/envs/myenv/lib/python3.11/site-packages/wandb/sdk/lib/sock_client.py", line 154, in send_server_request
    self._send_message(msg)
  File "/opt/anaconda3/envs/myenv/lib/python3.11/site-packages/wandb/sdk/lib/sock_client.py", line 151, in _send_message
    self._sendall_with_error_handle(header + data)
  File "/opt/anaconda3/envs/myenv/lib/python3.11/site-packages/wandb/sdk/lib/sock_client.py", line 130, in _sendall_with_error_handle
    sent = self._sock.send(data)
           ^^^^^^^^^^^^^^^^^^^^^
BrokenPipeError: [Errno 32] Broken pipe
2025-07-16 11:32:13,152 ERROR   MainThread:59013 [redirect.py:_on_write():664] [no run ID] error in stderr callback
Traceback (most recent call last):
  File "/opt/anaconda3/envs/myenv/lib/python3.11/site-packages/wandb/sdk/lib/redirect.py", line 662, in _on_write
    cb(written_data)
  File "/opt/anaconda3/envs/myenv/lib/python3.11/site-packages/wandb/sdk/wandb_run.py", line 2380, in <lambda>
    lambda data: self._console_raw_callback("stderr", data),
                 ^^^^^^^^^^^^^^^^^^^^^^^^^^^^^^^^^^^^^^^^^^
  File "/opt/anaconda3/envs/myenv/lib/python3.11/site-packages/wandb/sdk/wandb_run.py", line 391, in wrapper
    return func(self, *args, **kwargs)
           ^^^^^^^^^^^^^^^^^^^^^^^^^^^
  File "/opt/anaconda3/envs/myenv/lib/python3.11/site-packages/wandb/sdk/wandb_run.py", line 449, in wrapper_fn
    return func(self, *args, **kwargs)
           ^^^^^^^^^^^^^^^^^^^^^^^^^^^
  File "/opt/anaconda3/envs/myenv/lib/python3.11/site-packages/wandb/sdk/wandb_run.py", line 1561, in _console_raw_callback
    self._backend.interface.publish_output_raw(name, data)
  File "/opt/anaconda3/envs/myenv/lib/python3.11/site-packages/wandb/sdk/interface/interface.py", line 772, in publish_output_raw
    self._publish_output_raw(o)
  File "/opt/anaconda3/envs/myenv/lib/python3.11/site-packages/wandb/sdk/interface/interface_shared.py", line 38, in _publish_output_raw
    self._publish(rec)
  File "/opt/anaconda3/envs/myenv/lib/python3.11/site-packages/wandb/sdk/interface/interface_sock.py", line 39, in _publish
    self._sock_client.send_record_publish(record)
  File "/opt/anaconda3/envs/myenv/lib/python3.11/site-packages/wandb/sdk/lib/sock_client.py", line 174, in send_record_publish
    self.send_server_request(server_req)
  File "/opt/anaconda3/envs/myenv/lib/python3.11/site-packages/wandb/sdk/lib/sock_client.py", line 154, in send_server_request
    self._send_message(msg)
  File "/opt/anaconda3/envs/myenv/lib/python3.11/site-packages/wandb/sdk/lib/sock_client.py", line 151, in _send_message
    self._sendall_with_error_handle(header + data)
  File "/opt/anaconda3/envs/myenv/lib/python3.11/site-packages/wandb/sdk/lib/sock_client.py", line 130, in _sendall_with_error_handle
    sent = self._sock.send(data)
           ^^^^^^^^^^^^^^^^^^^^^
BrokenPipeError: [Errno 32] Broken pipe
2025-07-16 11:32:13,153 ERROR   MainThread:59013 [redirect.py:_on_write():664] [no run ID] error in stderr callback
Traceback (most recent call last):
  File "/opt/anaconda3/envs/myenv/lib/python3.11/site-packages/wandb/sdk/lib/redirect.py", line 662, in _on_write
    cb(written_data)
  File "/opt/anaconda3/envs/myenv/lib/python3.11/site-packages/wandb/sdk/wandb_run.py", line 2380, in <lambda>
    lambda data: self._console_raw_callback("stderr", data),
                 ^^^^^^^^^^^^^^^^^^^^^^^^^^^^^^^^^^^^^^^^^^
  File "/opt/anaconda3/envs/myenv/lib/python3.11/site-packages/wandb/sdk/wandb_run.py", line 391, in wrapper
    return func(self, *args, **kwargs)
           ^^^^^^^^^^^^^^^^^^^^^^^^^^^
  File "/opt/anaconda3/envs/myenv/lib/python3.11/site-packages/wandb/sdk/wandb_run.py", line 449, in wrapper_fn
    return func(self, *args, **kwargs)
           ^^^^^^^^^^^^^^^^^^^^^^^^^^^
  File "/opt/anaconda3/envs/myenv/lib/python3.11/site-packages/wandb/sdk/wandb_run.py", line 1561, in _console_raw_callback
    self._backend.interface.publish_output_raw(name, data)
  File "/opt/anaconda3/envs/myenv/lib/python3.11/site-packages/wandb/sdk/interface/interface.py", line 772, in publish_output_raw
    self._publish_output_raw(o)
  File "/opt/anaconda3/envs/myenv/lib/python3.11/site-packages/wandb/sdk/interface/interface_shared.py", line 38, in _publish_output_raw
    self._publish(rec)
  File "/opt/anaconda3/envs/myenv/lib/python3.11/site-packages/wandb/sdk/interface/interface_sock.py", line 39, in _publish
    self._sock_client.send_record_publish(record)
  File "/opt/anaconda3/envs/myenv/lib/python3.11/site-packages/wandb/sdk/lib/sock_client.py", line 174, in send_record_publish
    self.send_server_request(server_req)
  File "/opt/anaconda3/envs/myenv/lib/python3.11/site-packages/wandb/sdk/lib/sock_client.py", line 154, in send_server_request
    self._send_message(msg)
  File "/opt/anaconda3/envs/myenv/lib/python3.11/site-packages/wandb/sdk/lib/sock_client.py", line 151, in _send_message
    self._sendall_with_error_handle(header + data)
  File "/opt/anaconda3/envs/myenv/lib/python3.11/site-packages/wandb/sdk/lib/sock_client.py", line 130, in _sendall_with_error_handle
    sent = self._sock.send(data)
           ^^^^^^^^^^^^^^^^^^^^^
BrokenPipeError: [Errno 32] Broken pipe
2025-07-16 11:32:13,154 ERROR   MainThread:59013 [redirect.py:_on_write():664] [no run ID] error in stderr callback
Traceback (most recent call last):
  File "/opt/anaconda3/envs/myenv/lib/python3.11/site-packages/wandb/sdk/lib/redirect.py", line 662, in _on_write
    cb(written_data)
  File "/opt/anaconda3/envs/myenv/lib/python3.11/site-packages/wandb/sdk/wandb_run.py", line 2380, in <lambda>
    lambda data: self._console_raw_callback("stderr", data),
                 ^^^^^^^^^^^^^^^^^^^^^^^^^^^^^^^^^^^^^^^^^^
  File "/opt/anaconda3/envs/myenv/lib/python3.11/site-packages/wandb/sdk/wandb_run.py", line 391, in wrapper
    return func(self, *args, **kwargs)
           ^^^^^^^^^^^^^^^^^^^^^^^^^^^
  File "/opt/anaconda3/envs/myenv/lib/python3.11/site-packages/wandb/sdk/wandb_run.py", line 449, in wrapper_fn
    return func(self, *args, **kwargs)
           ^^^^^^^^^^^^^^^^^^^^^^^^^^^
  File "/opt/anaconda3/envs/myenv/lib/python3.11/site-packages/wandb/sdk/wandb_run.py", line 1561, in _console_raw_callback
    self._backend.interface.publish_output_raw(name, data)
  File "/opt/anaconda3/envs/myenv/lib/python3.11/site-packages/wandb/sdk/interface/interface.py", line 772, in publish_output_raw
    self._publish_output_raw(o)
  File "/opt/anaconda3/envs/myenv/lib/python3.11/site-packages/wandb/sdk/interface/interface_shared.py", line 38, in _publish_output_raw
    self._publish(rec)
  File "/opt/anaconda3/envs/myenv/lib/python3.11/site-packages/wandb/sdk/interface/interface_sock.py", line 39, in _publish
    self._sock_client.send_record_publish(record)
  File "/opt/anaconda3/envs/myenv/lib/python3.11/site-packages/wandb/sdk/lib/sock_client.py", line 174, in send_record_publish
    self.send_server_request(server_req)
  File "/opt/anaconda3/envs/myenv/lib/python3.11/site-packages/wandb/sdk/lib/sock_client.py", line 154, in send_server_request
    self._send_message(msg)
  File "/opt/anaconda3/envs/myenv/lib/python3.11/site-packages/wandb/sdk/lib/sock_client.py", line 151, in _send_message
    self._sendall_with_error_handle(header + data)
  File "/opt/anaconda3/envs/myenv/lib/python3.11/site-packages/wandb/sdk/lib/sock_client.py", line 130, in _sendall_with_error_handle
    sent = self._sock.send(data)
           ^^^^^^^^^^^^^^^^^^^^^
BrokenPipeError: [Errno 32] Broken pipe
2025-07-16 11:32:13,154 ERROR   MainThread:59013 [redirect.py:_on_write():664] [no run ID] error in stderr callback
Traceback (most recent call last):
  File "/opt/anaconda3/envs/myenv/lib/python3.11/site-packages/wandb/sdk/lib/redirect.py", line 662, in _on_write
    cb(written_data)
  File "/opt/anaconda3/envs/myenv/lib/python3.11/site-packages/wandb/sdk/wandb_run.py", line 2380, in <lambda>
    lambda data: self._console_raw_callback("stderr", data),
                 ^^^^^^^^^^^^^^^^^^^^^^^^^^^^^^^^^^^^^^^^^^
  File "/opt/anaconda3/envs/myenv/lib/python3.11/site-packages/wandb/sdk/wandb_run.py", line 391, in wrapper
    return func(self, *args, **kwargs)
           ^^^^^^^^^^^^^^^^^^^^^^^^^^^
  File "/opt/anaconda3/envs/myenv/lib/python3.11/site-packages/wandb/sdk/wandb_run.py", line 449, in wrapper_fn
    return func(self, *args, **kwargs)
           ^^^^^^^^^^^^^^^^^^^^^^^^^^^
  File "/opt/anaconda3/envs/myenv/lib/python3.11/site-packages/wandb/sdk/wandb_run.py", line 1561, in _console_raw_callback
    self._backend.interface.publish_output_raw(name, data)
  File "/opt/anaconda3/envs/myenv/lib/python3.11/site-packages/wandb/sdk/interface/interface.py", line 772, in publish_output_raw
    self._publish_output_raw(o)
  File "/opt/anaconda3/envs/myenv/lib/python3.11/site-packages/wandb/sdk/interface/interface_shared.py", line 38, in _publish_output_raw
    self._publish(rec)
  File "/opt/anaconda3/envs/myenv/lib/python3.11/site-packages/wandb/sdk/interface/interface_sock.py", line 39, in _publish
    self._sock_client.send_record_publish(record)
  File "/opt/anaconda3/envs/myenv/lib/python3.11/site-packages/wandb/sdk/lib/sock_client.py", line 174, in send_record_publish
    self.send_server_request(server_req)
  File "/opt/anaconda3/envs/myenv/lib/python3.11/site-packages/wandb/sdk/lib/sock_client.py", line 154, in send_server_request
    self._send_message(msg)
  File "/opt/anaconda3/envs/myenv/lib/python3.11/site-packages/wandb/sdk/lib/sock_client.py", line 151, in _send_message
    self._sendall_with_error_handle(header + data)
  File "/opt/anaconda3/envs/myenv/lib/python3.11/site-packages/wandb/sdk/lib/sock_client.py", line 130, in _sendall_with_error_handle
    sent = self._sock.send(data)
           ^^^^^^^^^^^^^^^^^^^^^
BrokenPipeError: [Errno 32] Broken pipe
2025-07-16 11:32:13,154 ERROR   MainThread:59013 [redirect.py:_on_write():664] [no run ID] error in stderr callback
Traceback (most recent call last):
  File "/opt/anaconda3/envs/myenv/lib/python3.11/site-packages/wandb/sdk/lib/redirect.py", line 662, in _on_write
    cb(written_data)
  File "/opt/anaconda3/envs/myenv/lib/python3.11/site-packages/wandb/sdk/wandb_run.py", line 2380, in <lambda>
    lambda data: self._console_raw_callback("stderr", data),
                 ^^^^^^^^^^^^^^^^^^^^^^^^^^^^^^^^^^^^^^^^^^
  File "/opt/anaconda3/envs/myenv/lib/python3.11/site-packages/wandb/sdk/wandb_run.py", line 391, in wrapper
    return func(self, *args, **kwargs)
           ^^^^^^^^^^^^^^^^^^^^^^^^^^^
  File "/opt/anaconda3/envs/myenv/lib/python3.11/site-packages/wandb/sdk/wandb_run.py", line 449, in wrapper_fn
    return func(self, *args, **kwargs)
           ^^^^^^^^^^^^^^^^^^^^^^^^^^^
  File "/opt/anaconda3/envs/myenv/lib/python3.11/site-packages/wandb/sdk/wandb_run.py", line 1561, in _console_raw_callback
    self._backend.interface.publish_output_raw(name, data)
  File "/opt/anaconda3/envs/myenv/lib/python3.11/site-packages/wandb/sdk/interface/interface.py", line 772, in publish_output_raw
    self._publish_output_raw(o)
  File "/opt/anaconda3/envs/myenv/lib/python3.11/site-packages/wandb/sdk/interface/interface_shared.py", line 38, in _publish_output_raw
    self._publish(rec)
  File "/opt/anaconda3/envs/myenv/lib/python3.11/site-packages/wandb/sdk/interface/interface_sock.py", line 39, in _publish
    self._sock_client.send_record_publish(record)
  File "/opt/anaconda3/envs/myenv/lib/python3.11/site-packages/wandb/sdk/lib/sock_client.py", line 174, in send_record_publish
    self.send_server_request(server_req)
  File "/opt/anaconda3/envs/myenv/lib/python3.11/site-packages/wandb/sdk/lib/sock_client.py", line 154, in send_server_request
    self._send_message(msg)
  File "/opt/anaconda3/envs/myenv/lib/python3.11/site-packages/wandb/sdk/lib/sock_client.py", line 151, in _send_message
    self._sendall_with_error_handle(header + data)
  File "/opt/anaconda3/envs/myenv/lib/python3.11/site-packages/wandb/sdk/lib/sock_client.py", line 130, in _sendall_with_error_handle
    sent = self._sock.send(data)
           ^^^^^^^^^^^^^^^^^^^^^
BrokenPipeError: [Errno 32] Broken pipe
2025-07-16 11:32:13,155 ERROR   MainThread:59013 [redirect.py:_on_write():664] [no run ID] error in stderr callback
Traceback (most recent call last):
  File "/opt/anaconda3/envs/myenv/lib/python3.11/site-packages/wandb/sdk/lib/redirect.py", line 662, in _on_write
    cb(written_data)
  File "/opt/anaconda3/envs/myenv/lib/python3.11/site-packages/wandb/sdk/wandb_run.py", line 2380, in <lambda>
    lambda data: self._console_raw_callback("stderr", data),
                 ^^^^^^^^^^^^^^^^^^^^^^^^^^^^^^^^^^^^^^^^^^
  File "/opt/anaconda3/envs/myenv/lib/python3.11/site-packages/wandb/sdk/wandb_run.py", line 391, in wrapper
    return func(self, *args, **kwargs)
           ^^^^^^^^^^^^^^^^^^^^^^^^^^^
  File "/opt/anaconda3/envs/myenv/lib/python3.11/site-packages/wandb/sdk/wandb_run.py", line 449, in wrapper_fn
    return func(self, *args, **kwargs)
           ^^^^^^^^^^^^^^^^^^^^^^^^^^^
  File "/opt/anaconda3/envs/myenv/lib/python3.11/site-packages/wandb/sdk/wandb_run.py", line 1561, in _console_raw_callback
    self._backend.interface.publish_output_raw(name, data)
  File "/opt/anaconda3/envs/myenv/lib/python3.11/site-packages/wandb/sdk/interface/interface.py", line 772, in publish_output_raw
    self._publish_output_raw(o)
  File "/opt/anaconda3/envs/myenv/lib/python3.11/site-packages/wandb/sdk/interface/interface_shared.py", line 38, in _publish_output_raw
    self._publish(rec)
  File "/opt/anaconda3/envs/myenv/lib/python3.11/site-packages/wandb/sdk/interface/interface_sock.py", line 39, in _publish
    self._sock_client.send_record_publish(record)
  File "/opt/anaconda3/envs/myenv/lib/python3.11/site-packages/wandb/sdk/lib/sock_client.py", line 174, in send_record_publish
    self.send_server_request(server_req)
  File "/opt/anaconda3/envs/myenv/lib/python3.11/site-packages/wandb/sdk/lib/sock_client.py", line 154, in send_server_request
    self._send_message(msg)
  File "/opt/anaconda3/envs/myenv/lib/python3.11/site-packages/wandb/sdk/lib/sock_client.py", line 151, in _send_message
    self._sendall_with_error_handle(header + data)
  File "/opt/anaconda3/envs/myenv/lib/python3.11/site-packages/wandb/sdk/lib/sock_client.py", line 130, in _sendall_with_error_handle
    sent = self._sock.send(data)
           ^^^^^^^^^^^^^^^^^^^^^
BrokenPipeError: [Errno 32] Broken pipe
2025-07-16 11:32:13,156 ERROR   MainThread:59013 [redirect.py:_on_write():664] [no run ID] error in stderr callback
Traceback (most recent call last):
  File "/opt/anaconda3/envs/myenv/lib/python3.11/site-packages/wandb/sdk/lib/redirect.py", line 662, in _on_write
    cb(written_data)
  File "/opt/anaconda3/envs/myenv/lib/python3.11/site-packages/wandb/sdk/wandb_run.py", line 2380, in <lambda>
    lambda data: self._console_raw_callback("stderr", data),
                 ^^^^^^^^^^^^^^^^^^^^^^^^^^^^^^^^^^^^^^^^^^
  File "/opt/anaconda3/envs/myenv/lib/python3.11/site-packages/wandb/sdk/wandb_run.py", line 391, in wrapper
    return func(self, *args, **kwargs)
           ^^^^^^^^^^^^^^^^^^^^^^^^^^^
  File "/opt/anaconda3/envs/myenv/lib/python3.11/site-packages/wandb/sdk/wandb_run.py", line 449, in wrapper_fn
    return func(self, *args, **kwargs)
           ^^^^^^^^^^^^^^^^^^^^^^^^^^^
  File "/opt/anaconda3/envs/myenv/lib/python3.11/site-packages/wandb/sdk/wandb_run.py", line 1561, in _console_raw_callback
    self._backend.interface.publish_output_raw(name, data)
  File "/opt/anaconda3/envs/myenv/lib/python3.11/site-packages/wandb/sdk/interface/interface.py", line 772, in publish_output_raw
    self._publish_output_raw(o)
  File "/opt/anaconda3/envs/myenv/lib/python3.11/site-packages/wandb/sdk/interface/interface_shared.py", line 38, in _publish_output_raw
    self._publish(rec)
  File "/opt/anaconda3/envs/myenv/lib/python3.11/site-packages/wandb/sdk/interface/interface_sock.py", line 39, in _publish
    self._sock_client.send_record_publish(record)
  File "/opt/anaconda3/envs/myenv/lib/python3.11/site-packages/wandb/sdk/lib/sock_client.py", line 174, in send_record_publish
    self.send_server_request(server_req)
  File "/opt/anaconda3/envs/myenv/lib/python3.11/site-packages/wandb/sdk/lib/sock_client.py", line 154, in send_server_request
    self._send_message(msg)
  File "/opt/anaconda3/envs/myenv/lib/python3.11/site-packages/wandb/sdk/lib/sock_client.py", line 151, in _send_message
    self._sendall_with_error_handle(header + data)
  File "/opt/anaconda3/envs/myenv/lib/python3.11/site-packages/wandb/sdk/lib/sock_client.py", line 130, in _sendall_with_error_handle
    sent = self._sock.send(data)
           ^^^^^^^^^^^^^^^^^^^^^
BrokenPipeError: [Errno 32] Broken pipe
2025-07-16 11:32:13,156 ERROR   MainThread:59013 [redirect.py:_on_write():664] [no run ID] error in stderr callback
Traceback (most recent call last):
  File "/opt/anaconda3/envs/myenv/lib/python3.11/site-packages/wandb/sdk/lib/redirect.py", line 662, in _on_write
    cb(written_data)
  File "/opt/anaconda3/envs/myenv/lib/python3.11/site-packages/wandb/sdk/wandb_run.py", line 2380, in <lambda>
    lambda data: self._console_raw_callback("stderr", data),
                 ^^^^^^^^^^^^^^^^^^^^^^^^^^^^^^^^^^^^^^^^^^
  File "/opt/anaconda3/envs/myenv/lib/python3.11/site-packages/wandb/sdk/wandb_run.py", line 391, in wrapper
    return func(self, *args, **kwargs)
           ^^^^^^^^^^^^^^^^^^^^^^^^^^^
  File "/opt/anaconda3/envs/myenv/lib/python3.11/site-packages/wandb/sdk/wandb_run.py", line 449, in wrapper_fn
    return func(self, *args, **kwargs)
           ^^^^^^^^^^^^^^^^^^^^^^^^^^^
  File "/opt/anaconda3/envs/myenv/lib/python3.11/site-packages/wandb/sdk/wandb_run.py", line 1561, in _console_raw_callback
    self._backend.interface.publish_output_raw(name, data)
  File "/opt/anaconda3/envs/myenv/lib/python3.11/site-packages/wandb/sdk/interface/interface.py", line 772, in publish_output_raw
    self._publish_output_raw(o)
  File "/opt/anaconda3/envs/myenv/lib/python3.11/site-packages/wandb/sdk/interface/interface_shared.py", line 38, in _publish_output_raw
    self._publish(rec)
  File "/opt/anaconda3/envs/myenv/lib/python3.11/site-packages/wandb/sdk/interface/interface_sock.py", line 39, in _publish
    self._sock_client.send_record_publish(record)
  File "/opt/anaconda3/envs/myenv/lib/python3.11/site-packages/wandb/sdk/lib/sock_client.py", line 174, in send_record_publish
    self.send_server_request(server_req)
  File "/opt/anaconda3/envs/myenv/lib/python3.11/site-packages/wandb/sdk/lib/sock_client.py", line 154, in send_server_request
    self._send_message(msg)
  File "/opt/anaconda3/envs/myenv/lib/python3.11/site-packages/wandb/sdk/lib/sock_client.py", line 151, in _send_message
    self._sendall_with_error_handle(header + data)
  File "/opt/anaconda3/envs/myenv/lib/python3.11/site-packages/wandb/sdk/lib/sock_client.py", line 130, in _sendall_with_error_handle
    sent = self._sock.send(data)
           ^^^^^^^^^^^^^^^^^^^^^
BrokenPipeError: [Errno 32] Broken pipe
2025-07-16 11:32:13,157 ERROR   MainThread:59013 [redirect.py:_on_write():664] [no run ID] error in stderr callback
Traceback (most recent call last):
  File "/opt/anaconda3/envs/myenv/lib/python3.11/site-packages/wandb/sdk/lib/redirect.py", line 662, in _on_write
    cb(written_data)
  File "/opt/anaconda3/envs/myenv/lib/python3.11/site-packages/wandb/sdk/wandb_run.py", line 2380, in <lambda>
    lambda data: self._console_raw_callback("stderr", data),
                 ^^^^^^^^^^^^^^^^^^^^^^^^^^^^^^^^^^^^^^^^^^
  File "/opt/anaconda3/envs/myenv/lib/python3.11/site-packages/wandb/sdk/wandb_run.py", line 391, in wrapper
    return func(self, *args, **kwargs)
           ^^^^^^^^^^^^^^^^^^^^^^^^^^^
  File "/opt/anaconda3/envs/myenv/lib/python3.11/site-packages/wandb/sdk/wandb_run.py", line 449, in wrapper_fn
    return func(self, *args, **kwargs)
           ^^^^^^^^^^^^^^^^^^^^^^^^^^^
  File "/opt/anaconda3/envs/myenv/lib/python3.11/site-packages/wandb/sdk/wandb_run.py", line 1561, in _console_raw_callback
    self._backend.interface.publish_output_raw(name, data)
  File "/opt/anaconda3/envs/myenv/lib/python3.11/site-packages/wandb/sdk/interface/interface.py", line 772, in publish_output_raw
    self._publish_output_raw(o)
  File "/opt/anaconda3/envs/myenv/lib/python3.11/site-packages/wandb/sdk/interface/interface_shared.py", line 38, in _publish_output_raw
    self._publish(rec)
  File "/opt/anaconda3/envs/myenv/lib/python3.11/site-packages/wandb/sdk/interface/interface_sock.py", line 39, in _publish
    self._sock_client.send_record_publish(record)
  File "/opt/anaconda3/envs/myenv/lib/python3.11/site-packages/wandb/sdk/lib/sock_client.py", line 174, in send_record_publish
    self.send_server_request(server_req)
  File "/opt/anaconda3/envs/myenv/lib/python3.11/site-packages/wandb/sdk/lib/sock_client.py", line 154, in send_server_request
    self._send_message(msg)
  File "/opt/anaconda3/envs/myenv/lib/python3.11/site-packages/wandb/sdk/lib/sock_client.py", line 151, in _send_message
    self._sendall_with_error_handle(header + data)
  File "/opt/anaconda3/envs/myenv/lib/python3.11/site-packages/wandb/sdk/lib/sock_client.py", line 130, in _sendall_with_error_handle
    sent = self._sock.send(data)
           ^^^^^^^^^^^^^^^^^^^^^
BrokenPipeError: [Errno 32] Broken pipe
2025-07-16 11:32:13,158 ERROR   MainThread:59013 [redirect.py:_on_write():664] [no run ID] error in stderr callback
Traceback (most recent call last):
  File "/opt/anaconda3/envs/myenv/lib/python3.11/site-packages/wandb/sdk/lib/redirect.py", line 662, in _on_write
    cb(written_data)
  File "/opt/anaconda3/envs/myenv/lib/python3.11/site-packages/wandb/sdk/wandb_run.py", line 2380, in <lambda>
    lambda data: self._console_raw_callback("stderr", data),
                 ^^^^^^^^^^^^^^^^^^^^^^^^^^^^^^^^^^^^^^^^^^
  File "/opt/anaconda3/envs/myenv/lib/python3.11/site-packages/wandb/sdk/wandb_run.py", line 391, in wrapper
    return func(self, *args, **kwargs)
           ^^^^^^^^^^^^^^^^^^^^^^^^^^^
  File "/opt/anaconda3/envs/myenv/lib/python3.11/site-packages/wandb/sdk/wandb_run.py", line 449, in wrapper_fn
    return func(self, *args, **kwargs)
           ^^^^^^^^^^^^^^^^^^^^^^^^^^^
  File "/opt/anaconda3/envs/myenv/lib/python3.11/site-packages/wandb/sdk/wandb_run.py", line 1561, in _console_raw_callback
    self._backend.interface.publish_output_raw(name, data)
  File "/opt/anaconda3/envs/myenv/lib/python3.11/site-packages/wandb/sdk/interface/interface.py", line 772, in publish_output_raw
    self._publish_output_raw(o)
  File "/opt/anaconda3/envs/myenv/lib/python3.11/site-packages/wandb/sdk/interface/interface_shared.py", line 38, in _publish_output_raw
    self._publish(rec)
  File "/opt/anaconda3/envs/myenv/lib/python3.11/site-packages/wandb/sdk/interface/interface_sock.py", line 39, in _publish
    self._sock_client.send_record_publish(record)
  File "/opt/anaconda3/envs/myenv/lib/python3.11/site-packages/wandb/sdk/lib/sock_client.py", line 174, in send_record_publish
    self.send_server_request(server_req)
  File "/opt/anaconda3/envs/myenv/lib/python3.11/site-packages/wandb/sdk/lib/sock_client.py", line 154, in send_server_request
    self._send_message(msg)
  File "/opt/anaconda3/envs/myenv/lib/python3.11/site-packages/wandb/sdk/lib/sock_client.py", line 151, in _send_message
    self._sendall_with_error_handle(header + data)
  File "/opt/anaconda3/envs/myenv/lib/python3.11/site-packages/wandb/sdk/lib/sock_client.py", line 130, in _sendall_with_error_handle
    sent = self._sock.send(data)
           ^^^^^^^^^^^^^^^^^^^^^
BrokenPipeError: [Errno 32] Broken pipe
2025-07-16 11:32:13,158 ERROR   MainThread:59013 [redirect.py:_on_write():664] [no run ID] error in stderr callback
Traceback (most recent call last):
  File "/opt/anaconda3/envs/myenv/lib/python3.11/site-packages/wandb/sdk/lib/redirect.py", line 662, in _on_write
    cb(written_data)
  File "/opt/anaconda3/envs/myenv/lib/python3.11/site-packages/wandb/sdk/wandb_run.py", line 2380, in <lambda>
    lambda data: self._console_raw_callback("stderr", data),
                 ^^^^^^^^^^^^^^^^^^^^^^^^^^^^^^^^^^^^^^^^^^
  File "/opt/anaconda3/envs/myenv/lib/python3.11/site-packages/wandb/sdk/wandb_run.py", line 391, in wrapper
    return func(self, *args, **kwargs)
           ^^^^^^^^^^^^^^^^^^^^^^^^^^^
  File "/opt/anaconda3/envs/myenv/lib/python3.11/site-packages/wandb/sdk/wandb_run.py", line 449, in wrapper_fn
    return func(self, *args, **kwargs)
           ^^^^^^^^^^^^^^^^^^^^^^^^^^^
  File "/opt/anaconda3/envs/myenv/lib/python3.11/site-packages/wandb/sdk/wandb_run.py", line 1561, in _console_raw_callback
    self._backend.interface.publish_output_raw(name, data)
  File "/opt/anaconda3/envs/myenv/lib/python3.11/site-packages/wandb/sdk/interface/interface.py", line 772, in publish_output_raw
    self._publish_output_raw(o)
  File "/opt/anaconda3/envs/myenv/lib/python3.11/site-packages/wandb/sdk/interface/interface_shared.py", line 38, in _publish_output_raw
    self._publish(rec)
  File "/opt/anaconda3/envs/myenv/lib/python3.11/site-packages/wandb/sdk/interface/interface_sock.py", line 39, in _publish
    self._sock_client.send_record_publish(record)
  File "/opt/anaconda3/envs/myenv/lib/python3.11/site-packages/wandb/sdk/lib/sock_client.py", line 174, in send_record_publish
    self.send_server_request(server_req)
  File "/opt/anaconda3/envs/myenv/lib/python3.11/site-packages/wandb/sdk/lib/sock_client.py", line 154, in send_server_request
    self._send_message(msg)
  File "/opt/anaconda3/envs/myenv/lib/python3.11/site-packages/wandb/sdk/lib/sock_client.py", line 151, in _send_message
    self._sendall_with_error_handle(header + data)
  File "/opt/anaconda3/envs/myenv/lib/python3.11/site-packages/wandb/sdk/lib/sock_client.py", line 130, in _sendall_with_error_handle
    sent = self._sock.send(data)
           ^^^^^^^^^^^^^^^^^^^^^
BrokenPipeError: [Errno 32] Broken pipe
2025-07-16 11:32:13,159 ERROR   MainThread:59013 [redirect.py:_on_write():664] [no run ID] error in stderr callback
Traceback (most recent call last):
  File "/opt/anaconda3/envs/myenv/lib/python3.11/site-packages/wandb/sdk/lib/redirect.py", line 662, in _on_write
    cb(written_data)
  File "/opt/anaconda3/envs/myenv/lib/python3.11/site-packages/wandb/sdk/wandb_run.py", line 2380, in <lambda>
    lambda data: self._console_raw_callback("stderr", data),
                 ^^^^^^^^^^^^^^^^^^^^^^^^^^^^^^^^^^^^^^^^^^
  File "/opt/anaconda3/envs/myenv/lib/python3.11/site-packages/wandb/sdk/wandb_run.py", line 391, in wrapper
    return func(self, *args, **kwargs)
           ^^^^^^^^^^^^^^^^^^^^^^^^^^^
  File "/opt/anaconda3/envs/myenv/lib/python3.11/site-packages/wandb/sdk/wandb_run.py", line 449, in wrapper_fn
    return func(self, *args, **kwargs)
           ^^^^^^^^^^^^^^^^^^^^^^^^^^^
  File "/opt/anaconda3/envs/myenv/lib/python3.11/site-packages/wandb/sdk/wandb_run.py", line 1561, in _console_raw_callback
    self._backend.interface.publish_output_raw(name, data)
  File "/opt/anaconda3/envs/myenv/lib/python3.11/site-packages/wandb/sdk/interface/interface.py", line 772, in publish_output_raw
    self._publish_output_raw(o)
  File "/opt/anaconda3/envs/myenv/lib/python3.11/site-packages/wandb/sdk/interface/interface_shared.py", line 38, in _publish_output_raw
    self._publish(rec)
  File "/opt/anaconda3/envs/myenv/lib/python3.11/site-packages/wandb/sdk/interface/interface_sock.py", line 39, in _publish
    self._sock_client.send_record_publish(record)
  File "/opt/anaconda3/envs/myenv/lib/python3.11/site-packages/wandb/sdk/lib/sock_client.py", line 174, in send_record_publish
    self.send_server_request(server_req)
  File "/opt/anaconda3/envs/myenv/lib/python3.11/site-packages/wandb/sdk/lib/sock_client.py", line 154, in send_server_request
    self._send_message(msg)
  File "/opt/anaconda3/envs/myenv/lib/python3.11/site-packages/wandb/sdk/lib/sock_client.py", line 151, in _send_message
    self._sendall_with_error_handle(header + data)
  File "/opt/anaconda3/envs/myenv/lib/python3.11/site-packages/wandb/sdk/lib/sock_client.py", line 130, in _sendall_with_error_handle
    sent = self._sock.send(data)
           ^^^^^^^^^^^^^^^^^^^^^
BrokenPipeError: [Errno 32] Broken pipe
2025-07-16 11:32:13,159 ERROR   MainThread:59013 [redirect.py:_on_write():664] [no run ID] error in stderr callback
Traceback (most recent call last):
  File "/opt/anaconda3/envs/myenv/lib/python3.11/site-packages/wandb/sdk/lib/redirect.py", line 662, in _on_write
    cb(written_data)
  File "/opt/anaconda3/envs/myenv/lib/python3.11/site-packages/wandb/sdk/wandb_run.py", line 2380, in <lambda>
    lambda data: self._console_raw_callback("stderr", data),
                 ^^^^^^^^^^^^^^^^^^^^^^^^^^^^^^^^^^^^^^^^^^
  File "/opt/anaconda3/envs/myenv/lib/python3.11/site-packages/wandb/sdk/wandb_run.py", line 391, in wrapper
    return func(self, *args, **kwargs)
           ^^^^^^^^^^^^^^^^^^^^^^^^^^^
  File "/opt/anaconda3/envs/myenv/lib/python3.11/site-packages/wandb/sdk/wandb_run.py", line 449, in wrapper_fn
    return func(self, *args, **kwargs)
           ^^^^^^^^^^^^^^^^^^^^^^^^^^^
  File "/opt/anaconda3/envs/myenv/lib/python3.11/site-packages/wandb/sdk/wandb_run.py", line 1561, in _console_raw_callback
    self._backend.interface.publish_output_raw(name, data)
  File "/opt/anaconda3/envs/myenv/lib/python3.11/site-packages/wandb/sdk/interface/interface.py", line 772, in publish_output_raw
    self._publish_output_raw(o)
  File "/opt/anaconda3/envs/myenv/lib/python3.11/site-packages/wandb/sdk/interface/interface_shared.py", line 38, in _publish_output_raw
    self._publish(rec)
  File "/opt/anaconda3/envs/myenv/lib/python3.11/site-packages/wandb/sdk/interface/interface_sock.py", line 39, in _publish
    self._sock_client.send_record_publish(record)
  File "/opt/anaconda3/envs/myenv/lib/python3.11/site-packages/wandb/sdk/lib/sock_client.py", line 174, in send_record_publish
    self.send_server_request(server_req)
  File "/opt/anaconda3/envs/myenv/lib/python3.11/site-packages/wandb/sdk/lib/sock_client.py", line 154, in send_server_request
    self._send_message(msg)
  File "/opt/anaconda3/envs/myenv/lib/python3.11/site-packages/wandb/sdk/lib/sock_client.py", line 151, in _send_message
    self._sendall_with_error_handle(header + data)
  File "/opt/anaconda3/envs/myenv/lib/python3.11/site-packages/wandb/sdk/lib/sock_client.py", line 130, in _sendall_with_error_handle
    sent = self._sock.send(data)
           ^^^^^^^^^^^^^^^^^^^^^
BrokenPipeError: [Errno 32] Broken pipe
2025-07-16 11:32:13,160 ERROR   MainThread:59013 [redirect.py:_on_write():664] [no run ID] error in stderr callback
Traceback (most recent call last):
  File "/opt/anaconda3/envs/myenv/lib/python3.11/site-packages/wandb/sdk/lib/redirect.py", line 662, in _on_write
    cb(written_data)
  File "/opt/anaconda3/envs/myenv/lib/python3.11/site-packages/wandb/sdk/wandb_run.py", line 2380, in <lambda>
    lambda data: self._console_raw_callback("stderr", data),
                 ^^^^^^^^^^^^^^^^^^^^^^^^^^^^^^^^^^^^^^^^^^
  File "/opt/anaconda3/envs/myenv/lib/python3.11/site-packages/wandb/sdk/wandb_run.py", line 391, in wrapper
    return func(self, *args, **kwargs)
           ^^^^^^^^^^^^^^^^^^^^^^^^^^^
  File "/opt/anaconda3/envs/myenv/lib/python3.11/site-packages/wandb/sdk/wandb_run.py", line 449, in wrapper_fn
    return func(self, *args, **kwargs)
           ^^^^^^^^^^^^^^^^^^^^^^^^^^^
  File "/opt/anaconda3/envs/myenv/lib/python3.11/site-packages/wandb/sdk/wandb_run.py", line 1561, in _console_raw_callback
    self._backend.interface.publish_output_raw(name, data)
  File "/opt/anaconda3/envs/myenv/lib/python3.11/site-packages/wandb/sdk/interface/interface.py", line 772, in publish_output_raw
    self._publish_output_raw(o)
  File "/opt/anaconda3/envs/myenv/lib/python3.11/site-packages/wandb/sdk/interface/interface_shared.py", line 38, in _publish_output_raw
    self._publish(rec)
  File "/opt/anaconda3/envs/myenv/lib/python3.11/site-packages/wandb/sdk/interface/interface_sock.py", line 39, in _publish
    self._sock_client.send_record_publish(record)
  File "/opt/anaconda3/envs/myenv/lib/python3.11/site-packages/wandb/sdk/lib/sock_client.py", line 174, in send_record_publish
    self.send_server_request(server_req)
  File "/opt/anaconda3/envs/myenv/lib/python3.11/site-packages/wandb/sdk/lib/sock_client.py", line 154, in send_server_request
    self._send_message(msg)
  File "/opt/anaconda3/envs/myenv/lib/python3.11/site-packages/wandb/sdk/lib/sock_client.py", line 151, in _send_message
    self._sendall_with_error_handle(header + data)
  File "/opt/anaconda3/envs/myenv/lib/python3.11/site-packages/wandb/sdk/lib/sock_client.py", line 130, in _sendall_with_error_handle
    sent = self._sock.send(data)
           ^^^^^^^^^^^^^^^^^^^^^
BrokenPipeError: [Errno 32] Broken pipe
2025-07-16 11:32:13,160 ERROR   MainThread:59013 [redirect.py:_on_write():664] [no run ID] error in stderr callback
Traceback (most recent call last):
  File "/opt/anaconda3/envs/myenv/lib/python3.11/site-packages/wandb/sdk/lib/redirect.py", line 662, in _on_write
    cb(written_data)
  File "/opt/anaconda3/envs/myenv/lib/python3.11/site-packages/wandb/sdk/wandb_run.py", line 2380, in <lambda>
    lambda data: self._console_raw_callback("stderr", data),
                 ^^^^^^^^^^^^^^^^^^^^^^^^^^^^^^^^^^^^^^^^^^
  File "/opt/anaconda3/envs/myenv/lib/python3.11/site-packages/wandb/sdk/wandb_run.py", line 391, in wrapper
    return func(self, *args, **kwargs)
           ^^^^^^^^^^^^^^^^^^^^^^^^^^^
  File "/opt/anaconda3/envs/myenv/lib/python3.11/site-packages/wandb/sdk/wandb_run.py", line 449, in wrapper_fn
    return func(self, *args, **kwargs)
           ^^^^^^^^^^^^^^^^^^^^^^^^^^^
  File "/opt/anaconda3/envs/myenv/lib/python3.11/site-packages/wandb/sdk/wandb_run.py", line 1561, in _console_raw_callback
    self._backend.interface.publish_output_raw(name, data)
  File "/opt/anaconda3/envs/myenv/lib/python3.11/site-packages/wandb/sdk/interface/interface.py", line 772, in publish_output_raw
    self._publish_output_raw(o)
  File "/opt/anaconda3/envs/myenv/lib/python3.11/site-packages/wandb/sdk/interface/interface_shared.py", line 38, in _publish_output_raw
    self._publish(rec)
  File "/opt/anaconda3/envs/myenv/lib/python3.11/site-packages/wandb/sdk/interface/interface_sock.py", line 39, in _publish
    self._sock_client.send_record_publish(record)
  File "/opt/anaconda3/envs/myenv/lib/python3.11/site-packages/wandb/sdk/lib/sock_client.py", line 174, in send_record_publish
    self.send_server_request(server_req)
  File "/opt/anaconda3/envs/myenv/lib/python3.11/site-packages/wandb/sdk/lib/sock_client.py", line 154, in send_server_request
    self._send_message(msg)
  File "/opt/anaconda3/envs/myenv/lib/python3.11/site-packages/wandb/sdk/lib/sock_client.py", line 151, in _send_message
    self._sendall_with_error_handle(header + data)
  File "/opt/anaconda3/envs/myenv/lib/python3.11/site-packages/wandb/sdk/lib/sock_client.py", line 130, in _sendall_with_error_handle
    sent = self._sock.send(data)
           ^^^^^^^^^^^^^^^^^^^^^
BrokenPipeError: [Errno 32] Broken pipe
2025-07-16 11:32:13,160 ERROR   MainThread:59013 [redirect.py:_on_write():664] [no run ID] error in stderr callback
Traceback (most recent call last):
  File "/opt/anaconda3/envs/myenv/lib/python3.11/site-packages/wandb/sdk/lib/redirect.py", line 662, in _on_write
    cb(written_data)
  File "/opt/anaconda3/envs/myenv/lib/python3.11/site-packages/wandb/sdk/wandb_run.py", line 2380, in <lambda>
    lambda data: self._console_raw_callback("stderr", data),
                 ^^^^^^^^^^^^^^^^^^^^^^^^^^^^^^^^^^^^^^^^^^
  File "/opt/anaconda3/envs/myenv/lib/python3.11/site-packages/wandb/sdk/wandb_run.py", line 391, in wrapper
    return func(self, *args, **kwargs)
           ^^^^^^^^^^^^^^^^^^^^^^^^^^^
  File "/opt/anaconda3/envs/myenv/lib/python3.11/site-packages/wandb/sdk/wandb_run.py", line 449, in wrapper_fn
    return func(self, *args, **kwargs)
           ^^^^^^^^^^^^^^^^^^^^^^^^^^^
  File "/opt/anaconda3/envs/myenv/lib/python3.11/site-packages/wandb/sdk/wandb_run.py", line 1561, in _console_raw_callback
    self._backend.interface.publish_output_raw(name, data)
  File "/opt/anaconda3/envs/myenv/lib/python3.11/site-packages/wandb/sdk/interface/interface.py", line 772, in publish_output_raw
    self._publish_output_raw(o)
  File "/opt/anaconda3/envs/myenv/lib/python3.11/site-packages/wandb/sdk/interface/interface_shared.py", line 38, in _publish_output_raw
    self._publish(rec)
  File "/opt/anaconda3/envs/myenv/lib/python3.11/site-packages/wandb/sdk/interface/interface_sock.py", line 39, in _publish
    self._sock_client.send_record_publish(record)
  File "/opt/anaconda3/envs/myenv/lib/python3.11/site-packages/wandb/sdk/lib/sock_client.py", line 174, in send_record_publish
    self.send_server_request(server_req)
  File "/opt/anaconda3/envs/myenv/lib/python3.11/site-packages/wandb/sdk/lib/sock_client.py", line 154, in send_server_request
    self._send_message(msg)
  File "/opt/anaconda3/envs/myenv/lib/python3.11/site-packages/wandb/sdk/lib/sock_client.py", line 151, in _send_message
    self._sendall_with_error_handle(header + data)
  File "/opt/anaconda3/envs/myenv/lib/python3.11/site-packages/wandb/sdk/lib/sock_client.py", line 130, in _sendall_with_error_handle
    sent = self._sock.send(data)
           ^^^^^^^^^^^^^^^^^^^^^
BrokenPipeError: [Errno 32] Broken pipe
2025-07-16 11:32:13,161 ERROR   MainThread:59013 [redirect.py:_on_write():664] [no run ID] error in stderr callback
Traceback (most recent call last):
  File "/opt/anaconda3/envs/myenv/lib/python3.11/site-packages/wandb/sdk/lib/redirect.py", line 662, in _on_write
    cb(written_data)
  File "/opt/anaconda3/envs/myenv/lib/python3.11/site-packages/wandb/sdk/wandb_run.py", line 2380, in <lambda>
    lambda data: self._console_raw_callback("stderr", data),
                 ^^^^^^^^^^^^^^^^^^^^^^^^^^^^^^^^^^^^^^^^^^
  File "/opt/anaconda3/envs/myenv/lib/python3.11/site-packages/wandb/sdk/wandb_run.py", line 391, in wrapper
    return func(self, *args, **kwargs)
           ^^^^^^^^^^^^^^^^^^^^^^^^^^^
  File "/opt/anaconda3/envs/myenv/lib/python3.11/site-packages/wandb/sdk/wandb_run.py", line 449, in wrapper_fn
    return func(self, *args, **kwargs)
           ^^^^^^^^^^^^^^^^^^^^^^^^^^^
  File "/opt/anaconda3/envs/myenv/lib/python3.11/site-packages/wandb/sdk/wandb_run.py", line 1561, in _console_raw_callback
    self._backend.interface.publish_output_raw(name, data)
  File "/opt/anaconda3/envs/myenv/lib/python3.11/site-packages/wandb/sdk/interface/interface.py", line 772, in publish_output_raw
    self._publish_output_raw(o)
  File "/opt/anaconda3/envs/myenv/lib/python3.11/site-packages/wandb/sdk/interface/interface_shared.py", line 38, in _publish_output_raw
    self._publish(rec)
  File "/opt/anaconda3/envs/myenv/lib/python3.11/site-packages/wandb/sdk/interface/interface_sock.py", line 39, in _publish
    self._sock_client.send_record_publish(record)
  File "/opt/anaconda3/envs/myenv/lib/python3.11/site-packages/wandb/sdk/lib/sock_client.py", line 174, in send_record_publish
    self.send_server_request(server_req)
  File "/opt/anaconda3/envs/myenv/lib/python3.11/site-packages/wandb/sdk/lib/sock_client.py", line 154, in send_server_request
    self._send_message(msg)
  File "/opt/anaconda3/envs/myenv/lib/python3.11/site-packages/wandb/sdk/lib/sock_client.py", line 151, in _send_message
    self._sendall_with_error_handle(header + data)
  File "/opt/anaconda3/envs/myenv/lib/python3.11/site-packages/wandb/sdk/lib/sock_client.py", line 130, in _sendall_with_error_handle
    sent = self._sock.send(data)
           ^^^^^^^^^^^^^^^^^^^^^
BrokenPipeError: [Errno 32] Broken pipe
2025-07-16 11:32:13,162 ERROR   MainThread:59013 [redirect.py:_on_write():664] [no run ID] error in stderr callback
Traceback (most recent call last):
  File "/opt/anaconda3/envs/myenv/lib/python3.11/site-packages/wandb/sdk/lib/redirect.py", line 662, in _on_write
    cb(written_data)
  File "/opt/anaconda3/envs/myenv/lib/python3.11/site-packages/wandb/sdk/wandb_run.py", line 2380, in <lambda>
    lambda data: self._console_raw_callback("stderr", data),
                 ^^^^^^^^^^^^^^^^^^^^^^^^^^^^^^^^^^^^^^^^^^
  File "/opt/anaconda3/envs/myenv/lib/python3.11/site-packages/wandb/sdk/wandb_run.py", line 391, in wrapper
    return func(self, *args, **kwargs)
           ^^^^^^^^^^^^^^^^^^^^^^^^^^^
  File "/opt/anaconda3/envs/myenv/lib/python3.11/site-packages/wandb/sdk/wandb_run.py", line 449, in wrapper_fn
    return func(self, *args, **kwargs)
           ^^^^^^^^^^^^^^^^^^^^^^^^^^^
  File "/opt/anaconda3/envs/myenv/lib/python3.11/site-packages/wandb/sdk/wandb_run.py", line 1561, in _console_raw_callback
    self._backend.interface.publish_output_raw(name, data)
  File "/opt/anaconda3/envs/myenv/lib/python3.11/site-packages/wandb/sdk/interface/interface.py", line 772, in publish_output_raw
    self._publish_output_raw(o)
  File "/opt/anaconda3/envs/myenv/lib/python3.11/site-packages/wandb/sdk/interface/interface_shared.py", line 38, in _publish_output_raw
    self._publish(rec)
  File "/opt/anaconda3/envs/myenv/lib/python3.11/site-packages/wandb/sdk/interface/interface_sock.py", line 39, in _publish
    self._sock_client.send_record_publish(record)
  File "/opt/anaconda3/envs/myenv/lib/python3.11/site-packages/wandb/sdk/lib/sock_client.py", line 174, in send_record_publish
    self.send_server_request(server_req)
  File "/opt/anaconda3/envs/myenv/lib/python3.11/site-packages/wandb/sdk/lib/sock_client.py", line 154, in send_server_request
    self._send_message(msg)
  File "/opt/anaconda3/envs/myenv/lib/python3.11/site-packages/wandb/sdk/lib/sock_client.py", line 151, in _send_message
    self._sendall_with_error_handle(header + data)
  File "/opt/anaconda3/envs/myenv/lib/python3.11/site-packages/wandb/sdk/lib/sock_client.py", line 130, in _sendall_with_error_handle
    sent = self._sock.send(data)
           ^^^^^^^^^^^^^^^^^^^^^
BrokenPipeError: [Errno 32] Broken pipe
2025-07-16 11:32:13,162 ERROR   MainThread:59013 [redirect.py:_on_write():664] [no run ID] error in stderr callback
Traceback (most recent call last):
  File "/opt/anaconda3/envs/myenv/lib/python3.11/site-packages/wandb/sdk/lib/redirect.py", line 662, in _on_write
    cb(written_data)
  File "/opt/anaconda3/envs/myenv/lib/python3.11/site-packages/wandb/sdk/wandb_run.py", line 2380, in <lambda>
    lambda data: self._console_raw_callback("stderr", data),
                 ^^^^^^^^^^^^^^^^^^^^^^^^^^^^^^^^^^^^^^^^^^
  File "/opt/anaconda3/envs/myenv/lib/python3.11/site-packages/wandb/sdk/wandb_run.py", line 391, in wrapper
    return func(self, *args, **kwargs)
           ^^^^^^^^^^^^^^^^^^^^^^^^^^^
  File "/opt/anaconda3/envs/myenv/lib/python3.11/site-packages/wandb/sdk/wandb_run.py", line 449, in wrapper_fn
    return func(self, *args, **kwargs)
           ^^^^^^^^^^^^^^^^^^^^^^^^^^^
  File "/opt/anaconda3/envs/myenv/lib/python3.11/site-packages/wandb/sdk/wandb_run.py", line 1561, in _console_raw_callback
    self._backend.interface.publish_output_raw(name, data)
  File "/opt/anaconda3/envs/myenv/lib/python3.11/site-packages/wandb/sdk/interface/interface.py", line 772, in publish_output_raw
    self._publish_output_raw(o)
  File "/opt/anaconda3/envs/myenv/lib/python3.11/site-packages/wandb/sdk/interface/interface_shared.py", line 38, in _publish_output_raw
    self._publish(rec)
  File "/opt/anaconda3/envs/myenv/lib/python3.11/site-packages/wandb/sdk/interface/interface_sock.py", line 39, in _publish
    self._sock_client.send_record_publish(record)
  File "/opt/anaconda3/envs/myenv/lib/python3.11/site-packages/wandb/sdk/lib/sock_client.py", line 174, in send_record_publish
    self.send_server_request(server_req)
  File "/opt/anaconda3/envs/myenv/lib/python3.11/site-packages/wandb/sdk/lib/sock_client.py", line 154, in send_server_request
    self._send_message(msg)
  File "/opt/anaconda3/envs/myenv/lib/python3.11/site-packages/wandb/sdk/lib/sock_client.py", line 151, in _send_message
    self._sendall_with_error_handle(header + data)
  File "/opt/anaconda3/envs/myenv/lib/python3.11/site-packages/wandb/sdk/lib/sock_client.py", line 130, in _sendall_with_error_handle
    sent = self._sock.send(data)
           ^^^^^^^^^^^^^^^^^^^^^
BrokenPipeError: [Errno 32] Broken pipe
2025-07-16 11:32:13,162 ERROR   MainThread:59013 [redirect.py:_on_write():664] [no run ID] error in stderr callback
Traceback (most recent call last):
  File "/opt/anaconda3/envs/myenv/lib/python3.11/site-packages/wandb/sdk/lib/redirect.py", line 662, in _on_write
    cb(written_data)
  File "/opt/anaconda3/envs/myenv/lib/python3.11/site-packages/wandb/sdk/wandb_run.py", line 2380, in <lambda>
    lambda data: self._console_raw_callback("stderr", data),
                 ^^^^^^^^^^^^^^^^^^^^^^^^^^^^^^^^^^^^^^^^^^
  File "/opt/anaconda3/envs/myenv/lib/python3.11/site-packages/wandb/sdk/wandb_run.py", line 391, in wrapper
    return func(self, *args, **kwargs)
           ^^^^^^^^^^^^^^^^^^^^^^^^^^^
  File "/opt/anaconda3/envs/myenv/lib/python3.11/site-packages/wandb/sdk/wandb_run.py", line 449, in wrapper_fn
    return func(self, *args, **kwargs)
           ^^^^^^^^^^^^^^^^^^^^^^^^^^^
  File "/opt/anaconda3/envs/myenv/lib/python3.11/site-packages/wandb/sdk/wandb_run.py", line 1561, in _console_raw_callback
    self._backend.interface.publish_output_raw(name, data)
  File "/opt/anaconda3/envs/myenv/lib/python3.11/site-packages/wandb/sdk/interface/interface.py", line 772, in publish_output_raw
    self._publish_output_raw(o)
  File "/opt/anaconda3/envs/myenv/lib/python3.11/site-packages/wandb/sdk/interface/interface_shared.py", line 38, in _publish_output_raw
    self._publish(rec)
  File "/opt/anaconda3/envs/myenv/lib/python3.11/site-packages/wandb/sdk/interface/interface_sock.py", line 39, in _publish
    self._sock_client.send_record_publish(record)
  File "/opt/anaconda3/envs/myenv/lib/python3.11/site-packages/wandb/sdk/lib/sock_client.py", line 174, in send_record_publish
    self.send_server_request(server_req)
  File "/opt/anaconda3/envs/myenv/lib/python3.11/site-packages/wandb/sdk/lib/sock_client.py", line 154, in send_server_request
    self._send_message(msg)
  File "/opt/anaconda3/envs/myenv/lib/python3.11/site-packages/wandb/sdk/lib/sock_client.py", line 151, in _send_message
    self._sendall_with_error_handle(header + data)
  File "/opt/anaconda3/envs/myenv/lib/python3.11/site-packages/wandb/sdk/lib/sock_client.py", line 130, in _sendall_with_error_handle
    sent = self._sock.send(data)
           ^^^^^^^^^^^^^^^^^^^^^
BrokenPipeError: [Errno 32] Broken pipe
2025-07-16 11:32:13,162 ERROR   MainThread:59013 [redirect.py:_on_write():664] [no run ID] error in stderr callback
Traceback (most recent call last):
  File "/opt/anaconda3/envs/myenv/lib/python3.11/site-packages/wandb/sdk/lib/redirect.py", line 662, in _on_write
    cb(written_data)
  File "/opt/anaconda3/envs/myenv/lib/python3.11/site-packages/wandb/sdk/wandb_run.py", line 2380, in <lambda>
    lambda data: self._console_raw_callback("stderr", data),
                 ^^^^^^^^^^^^^^^^^^^^^^^^^^^^^^^^^^^^^^^^^^
  File "/opt/anaconda3/envs/myenv/lib/python3.11/site-packages/wandb/sdk/wandb_run.py", line 391, in wrapper
    return func(self, *args, **kwargs)
           ^^^^^^^^^^^^^^^^^^^^^^^^^^^
  File "/opt/anaconda3/envs/myenv/lib/python3.11/site-packages/wandb/sdk/wandb_run.py", line 449, in wrapper_fn
    return func(self, *args, **kwargs)
           ^^^^^^^^^^^^^^^^^^^^^^^^^^^
  File "/opt/anaconda3/envs/myenv/lib/python3.11/site-packages/wandb/sdk/wandb_run.py", line 1561, in _console_raw_callback
    self._backend.interface.publish_output_raw(name, data)
  File "/opt/anaconda3/envs/myenv/lib/python3.11/site-packages/wandb/sdk/interface/interface.py", line 772, in publish_output_raw
    self._publish_output_raw(o)
  File "/opt/anaconda3/envs/myenv/lib/python3.11/site-packages/wandb/sdk/interface/interface_shared.py", line 38, in _publish_output_raw
    self._publish(rec)
  File "/opt/anaconda3/envs/myenv/lib/python3.11/site-packages/wandb/sdk/interface/interface_sock.py", line 39, in _publish
    self._sock_client.send_record_publish(record)
  File "/opt/anaconda3/envs/myenv/lib/python3.11/site-packages/wandb/sdk/lib/sock_client.py", line 174, in send_record_publish
    self.send_server_request(server_req)
  File "/opt/anaconda3/envs/myenv/lib/python3.11/site-packages/wandb/sdk/lib/sock_client.py", line 154, in send_server_request
    self._send_message(msg)
  File "/opt/anaconda3/envs/myenv/lib/python3.11/site-packages/wandb/sdk/lib/sock_client.py", line 151, in _send_message
    self._sendall_with_error_handle(header + data)
  File "/opt/anaconda3/envs/myenv/lib/python3.11/site-packages/wandb/sdk/lib/sock_client.py", line 130, in _sendall_with_error_handle
    sent = self._sock.send(data)
           ^^^^^^^^^^^^^^^^^^^^^
BrokenPipeError: [Errno 32] Broken pipe
2025-07-16 11:32:13,163 ERROR   MainThread:59013 [redirect.py:_on_write():664] [no run ID] error in stderr callback
Traceback (most recent call last):
  File "/opt/anaconda3/envs/myenv/lib/python3.11/site-packages/wandb/sdk/lib/redirect.py", line 662, in _on_write
    cb(written_data)
  File "/opt/anaconda3/envs/myenv/lib/python3.11/site-packages/wandb/sdk/wandb_run.py", line 2380, in <lambda>
    lambda data: self._console_raw_callback("stderr", data),
                 ^^^^^^^^^^^^^^^^^^^^^^^^^^^^^^^^^^^^^^^^^^
  File "/opt/anaconda3/envs/myenv/lib/python3.11/site-packages/wandb/sdk/wandb_run.py", line 391, in wrapper
    return func(self, *args, **kwargs)
           ^^^^^^^^^^^^^^^^^^^^^^^^^^^
  File "/opt/anaconda3/envs/myenv/lib/python3.11/site-packages/wandb/sdk/wandb_run.py", line 449, in wrapper_fn
    return func(self, *args, **kwargs)
           ^^^^^^^^^^^^^^^^^^^^^^^^^^^
  File "/opt/anaconda3/envs/myenv/lib/python3.11/site-packages/wandb/sdk/wandb_run.py", line 1561, in _console_raw_callback
    self._backend.interface.publish_output_raw(name, data)
  File "/opt/anaconda3/envs/myenv/lib/python3.11/site-packages/wandb/sdk/interface/interface.py", line 772, in publish_output_raw
    self._publish_output_raw(o)
  File "/opt/anaconda3/envs/myenv/lib/python3.11/site-packages/wandb/sdk/interface/interface_shared.py", line 38, in _publish_output_raw
    self._publish(rec)
  File "/opt/anaconda3/envs/myenv/lib/python3.11/site-packages/wandb/sdk/interface/interface_sock.py", line 39, in _publish
    self._sock_client.send_record_publish(record)
  File "/opt/anaconda3/envs/myenv/lib/python3.11/site-packages/wandb/sdk/lib/sock_client.py", line 174, in send_record_publish
    self.send_server_request(server_req)
  File "/opt/anaconda3/envs/myenv/lib/python3.11/site-packages/wandb/sdk/lib/sock_client.py", line 154, in send_server_request
    self._send_message(msg)
  File "/opt/anaconda3/envs/myenv/lib/python3.11/site-packages/wandb/sdk/lib/sock_client.py", line 151, in _send_message
    self._sendall_with_error_handle(header + data)
  File "/opt/anaconda3/envs/myenv/lib/python3.11/site-packages/wandb/sdk/lib/sock_client.py", line 130, in _sendall_with_error_handle
    sent = self._sock.send(data)
           ^^^^^^^^^^^^^^^^^^^^^
BrokenPipeError: [Errno 32] Broken pipe
2025-07-16 11:32:13,163 ERROR   MainThread:59013 [redirect.py:_on_write():664] [no run ID] error in stderr callback
Traceback (most recent call last):
  File "/opt/anaconda3/envs/myenv/lib/python3.11/site-packages/wandb/sdk/lib/redirect.py", line 662, in _on_write
    cb(written_data)
  File "/opt/anaconda3/envs/myenv/lib/python3.11/site-packages/wandb/sdk/wandb_run.py", line 2380, in <lambda>
    lambda data: self._console_raw_callback("stderr", data),
                 ^^^^^^^^^^^^^^^^^^^^^^^^^^^^^^^^^^^^^^^^^^
  File "/opt/anaconda3/envs/myenv/lib/python3.11/site-packages/wandb/sdk/wandb_run.py", line 391, in wrapper
    return func(self, *args, **kwargs)
           ^^^^^^^^^^^^^^^^^^^^^^^^^^^
  File "/opt/anaconda3/envs/myenv/lib/python3.11/site-packages/wandb/sdk/wandb_run.py", line 449, in wrapper_fn
    return func(self, *args, **kwargs)
           ^^^^^^^^^^^^^^^^^^^^^^^^^^^
  File "/opt/anaconda3/envs/myenv/lib/python3.11/site-packages/wandb/sdk/wandb_run.py", line 1561, in _console_raw_callback
    self._backend.interface.publish_output_raw(name, data)
  File "/opt/anaconda3/envs/myenv/lib/python3.11/site-packages/wandb/sdk/interface/interface.py", line 772, in publish_output_raw
    self._publish_output_raw(o)
  File "/opt/anaconda3/envs/myenv/lib/python3.11/site-packages/wandb/sdk/interface/interface_shared.py", line 38, in _publish_output_raw
    self._publish(rec)
  File "/opt/anaconda3/envs/myenv/lib/python3.11/site-packages/wandb/sdk/interface/interface_sock.py", line 39, in _publish
    self._sock_client.send_record_publish(record)
  File "/opt/anaconda3/envs/myenv/lib/python3.11/site-packages/wandb/sdk/lib/sock_client.py", line 174, in send_record_publish
    self.send_server_request(server_req)
  File "/opt/anaconda3/envs/myenv/lib/python3.11/site-packages/wandb/sdk/lib/sock_client.py", line 154, in send_server_request
    self._send_message(msg)
  File "/opt/anaconda3/envs/myenv/lib/python3.11/site-packages/wandb/sdk/lib/sock_client.py", line 151, in _send_message
    self._sendall_with_error_handle(header + data)
  File "/opt/anaconda3/envs/myenv/lib/python3.11/site-packages/wandb/sdk/lib/sock_client.py", line 130, in _sendall_with_error_handle
    sent = self._sock.send(data)
           ^^^^^^^^^^^^^^^^^^^^^
BrokenPipeError: [Errno 32] Broken pipe
2025-07-16 11:32:13,163 ERROR   MainThread:59013 [redirect.py:_on_write():664] [no run ID] error in stderr callback
Traceback (most recent call last):
  File "/opt/anaconda3/envs/myenv/lib/python3.11/site-packages/wandb/sdk/lib/redirect.py", line 662, in _on_write
    cb(written_data)
  File "/opt/anaconda3/envs/myenv/lib/python3.11/site-packages/wandb/sdk/wandb_run.py", line 2380, in <lambda>
    lambda data: self._console_raw_callback("stderr", data),
                 ^^^^^^^^^^^^^^^^^^^^^^^^^^^^^^^^^^^^^^^^^^
  File "/opt/anaconda3/envs/myenv/lib/python3.11/site-packages/wandb/sdk/wandb_run.py", line 391, in wrapper
    return func(self, *args, **kwargs)
           ^^^^^^^^^^^^^^^^^^^^^^^^^^^
  File "/opt/anaconda3/envs/myenv/lib/python3.11/site-packages/wandb/sdk/wandb_run.py", line 449, in wrapper_fn
    return func(self, *args, **kwargs)
           ^^^^^^^^^^^^^^^^^^^^^^^^^^^
  File "/opt/anaconda3/envs/myenv/lib/python3.11/site-packages/wandb/sdk/wandb_run.py", line 1561, in _console_raw_callback
    self._backend.interface.publish_output_raw(name, data)
  File "/opt/anaconda3/envs/myenv/lib/python3.11/site-packages/wandb/sdk/interface/interface.py", line 772, in publish_output_raw
    self._publish_output_raw(o)
  File "/opt/anaconda3/envs/myenv/lib/python3.11/site-packages/wandb/sdk/interface/interface_shared.py", line 38, in _publish_output_raw
    self._publish(rec)
  File "/opt/anaconda3/envs/myenv/lib/python3.11/site-packages/wandb/sdk/interface/interface_sock.py", line 39, in _publish
    self._sock_client.send_record_publish(record)
  File "/opt/anaconda3/envs/myenv/lib/python3.11/site-packages/wandb/sdk/lib/sock_client.py", line 174, in send_record_publish
    self.send_server_request(server_req)
  File "/opt/anaconda3/envs/myenv/lib/python3.11/site-packages/wandb/sdk/lib/sock_client.py", line 154, in send_server_request
    self._send_message(msg)
  File "/opt/anaconda3/envs/myenv/lib/python3.11/site-packages/wandb/sdk/lib/sock_client.py", line 151, in _send_message
    self._sendall_with_error_handle(header + data)
  File "/opt/anaconda3/envs/myenv/lib/python3.11/site-packages/wandb/sdk/lib/sock_client.py", line 130, in _sendall_with_error_handle
    sent = self._sock.send(data)
           ^^^^^^^^^^^^^^^^^^^^^
BrokenPipeError: [Errno 32] Broken pipe
2025-07-16 11:32:13,164 ERROR   MainThread:59013 [redirect.py:_on_write():664] [no run ID] error in stderr callback
Traceback (most recent call last):
  File "/opt/anaconda3/envs/myenv/lib/python3.11/site-packages/wandb/sdk/lib/redirect.py", line 662, in _on_write
    cb(written_data)
  File "/opt/anaconda3/envs/myenv/lib/python3.11/site-packages/wandb/sdk/wandb_run.py", line 2380, in <lambda>
    lambda data: self._console_raw_callback("stderr", data),
                 ^^^^^^^^^^^^^^^^^^^^^^^^^^^^^^^^^^^^^^^^^^
  File "/opt/anaconda3/envs/myenv/lib/python3.11/site-packages/wandb/sdk/wandb_run.py", line 391, in wrapper
    return func(self, *args, **kwargs)
           ^^^^^^^^^^^^^^^^^^^^^^^^^^^
  File "/opt/anaconda3/envs/myenv/lib/python3.11/site-packages/wandb/sdk/wandb_run.py", line 449, in wrapper_fn
    return func(self, *args, **kwargs)
           ^^^^^^^^^^^^^^^^^^^^^^^^^^^
  File "/opt/anaconda3/envs/myenv/lib/python3.11/site-packages/wandb/sdk/wandb_run.py", line 1561, in _console_raw_callback
    self._backend.interface.publish_output_raw(name, data)
  File "/opt/anaconda3/envs/myenv/lib/python3.11/site-packages/wandb/sdk/interface/interface.py", line 772, in publish_output_raw
    self._publish_output_raw(o)
  File "/opt/anaconda3/envs/myenv/lib/python3.11/site-packages/wandb/sdk/interface/interface_shared.py", line 38, in _publish_output_raw
    self._publish(rec)
  File "/opt/anaconda3/envs/myenv/lib/python3.11/site-packages/wandb/sdk/interface/interface_sock.py", line 39, in _publish
    self._sock_client.send_record_publish(record)
  File "/opt/anaconda3/envs/myenv/lib/python3.11/site-packages/wandb/sdk/lib/sock_client.py", line 174, in send_record_publish
    self.send_server_request(server_req)
  File "/opt/anaconda3/envs/myenv/lib/python3.11/site-packages/wandb/sdk/lib/sock_client.py", line 154, in send_server_request
    self._send_message(msg)
  File "/opt/anaconda3/envs/myenv/lib/python3.11/site-packages/wandb/sdk/lib/sock_client.py", line 151, in _send_message
    self._sendall_with_error_handle(header + data)
  File "/opt/anaconda3/envs/myenv/lib/python3.11/site-packages/wandb/sdk/lib/sock_client.py", line 130, in _sendall_with_error_handle
    sent = self._sock.send(data)
           ^^^^^^^^^^^^^^^^^^^^^
BrokenPipeError: [Errno 32] Broken pipe
2025-07-16 11:32:13,164 ERROR   MainThread:59013 [redirect.py:_on_write():664] [no run ID] error in stderr callback
Traceback (most recent call last):
  File "/opt/anaconda3/envs/myenv/lib/python3.11/site-packages/wandb/sdk/lib/redirect.py", line 662, in _on_write
    cb(written_data)
  File "/opt/anaconda3/envs/myenv/lib/python3.11/site-packages/wandb/sdk/wandb_run.py", line 2380, in <lambda>
    lambda data: self._console_raw_callback("stderr", data),
                 ^^^^^^^^^^^^^^^^^^^^^^^^^^^^^^^^^^^^^^^^^^
  File "/opt/anaconda3/envs/myenv/lib/python3.11/site-packages/wandb/sdk/wandb_run.py", line 391, in wrapper
    return func(self, *args, **kwargs)
           ^^^^^^^^^^^^^^^^^^^^^^^^^^^
  File "/opt/anaconda3/envs/myenv/lib/python3.11/site-packages/wandb/sdk/wandb_run.py", line 449, in wrapper_fn
    return func(self, *args, **kwargs)
           ^^^^^^^^^^^^^^^^^^^^^^^^^^^
  File "/opt/anaconda3/envs/myenv/lib/python3.11/site-packages/wandb/sdk/wandb_run.py", line 1561, in _console_raw_callback
    self._backend.interface.publish_output_raw(name, data)
  File "/opt/anaconda3/envs/myenv/lib/python3.11/site-packages/wandb/sdk/interface/interface.py", line 772, in publish_output_raw
    self._publish_output_raw(o)
  File "/opt/anaconda3/envs/myenv/lib/python3.11/site-packages/wandb/sdk/interface/interface_shared.py", line 38, in _publish_output_raw
    self._publish(rec)
  File "/opt/anaconda3/envs/myenv/lib/python3.11/site-packages/wandb/sdk/interface/interface_sock.py", line 39, in _publish
    self._sock_client.send_record_publish(record)
  File "/opt/anaconda3/envs/myenv/lib/python3.11/site-packages/wandb/sdk/lib/sock_client.py", line 174, in send_record_publish
    self.send_server_request(server_req)
  File "/opt/anaconda3/envs/myenv/lib/python3.11/site-packages/wandb/sdk/lib/sock_client.py", line 154, in send_server_request
    self._send_message(msg)
  File "/opt/anaconda3/envs/myenv/lib/python3.11/site-packages/wandb/sdk/lib/sock_client.py", line 151, in _send_message
    self._sendall_with_error_handle(header + data)
  File "/opt/anaconda3/envs/myenv/lib/python3.11/site-packages/wandb/sdk/lib/sock_client.py", line 130, in _sendall_with_error_handle
    sent = self._sock.send(data)
           ^^^^^^^^^^^^^^^^^^^^^
BrokenPipeError: [Errno 32] Broken pipe
2025-07-16 11:32:13,164 ERROR   MainThread:59013 [redirect.py:_on_write():664] [no run ID] error in stderr callback
Traceback (most recent call last):
  File "/opt/anaconda3/envs/myenv/lib/python3.11/site-packages/wandb/sdk/lib/redirect.py", line 662, in _on_write
    cb(written_data)
  File "/opt/anaconda3/envs/myenv/lib/python3.11/site-packages/wandb/sdk/wandb_run.py", line 2380, in <lambda>
    lambda data: self._console_raw_callback("stderr", data),
                 ^^^^^^^^^^^^^^^^^^^^^^^^^^^^^^^^^^^^^^^^^^
  File "/opt/anaconda3/envs/myenv/lib/python3.11/site-packages/wandb/sdk/wandb_run.py", line 391, in wrapper
    return func(self, *args, **kwargs)
           ^^^^^^^^^^^^^^^^^^^^^^^^^^^
  File "/opt/anaconda3/envs/myenv/lib/python3.11/site-packages/wandb/sdk/wandb_run.py", line 449, in wrapper_fn
    return func(self, *args, **kwargs)
           ^^^^^^^^^^^^^^^^^^^^^^^^^^^
  File "/opt/anaconda3/envs/myenv/lib/python3.11/site-packages/wandb/sdk/wandb_run.py", line 1561, in _console_raw_callback
    self._backend.interface.publish_output_raw(name, data)
  File "/opt/anaconda3/envs/myenv/lib/python3.11/site-packages/wandb/sdk/interface/interface.py", line 772, in publish_output_raw
    self._publish_output_raw(o)
  File "/opt/anaconda3/envs/myenv/lib/python3.11/site-packages/wandb/sdk/interface/interface_shared.py", line 38, in _publish_output_raw
    self._publish(rec)
  File "/opt/anaconda3/envs/myenv/lib/python3.11/site-packages/wandb/sdk/interface/interface_sock.py", line 39, in _publish
    self._sock_client.send_record_publish(record)
  File "/opt/anaconda3/envs/myenv/lib/python3.11/site-packages/wandb/sdk/lib/sock_client.py", line 174, in send_record_publish
    self.send_server_request(server_req)
  File "/opt/anaconda3/envs/myenv/lib/python3.11/site-packages/wandb/sdk/lib/sock_client.py", line 154, in send_server_request
    self._send_message(msg)
  File "/opt/anaconda3/envs/myenv/lib/python3.11/site-packages/wandb/sdk/lib/sock_client.py", line 151, in _send_message
    self._sendall_with_error_handle(header + data)
  File "/opt/anaconda3/envs/myenv/lib/python3.11/site-packages/wandb/sdk/lib/sock_client.py", line 130, in _sendall_with_error_handle
    sent = self._sock.send(data)
           ^^^^^^^^^^^^^^^^^^^^^
BrokenPipeError: [Errno 32] Broken pipe
2025-07-16 11:32:13,165 ERROR   MainThread:59013 [redirect.py:_on_write():664] [no run ID] error in stderr callback
Traceback (most recent call last):
  File "/opt/anaconda3/envs/myenv/lib/python3.11/site-packages/wandb/sdk/lib/redirect.py", line 662, in _on_write
    cb(written_data)
  File "/opt/anaconda3/envs/myenv/lib/python3.11/site-packages/wandb/sdk/wandb_run.py", line 2380, in <lambda>
    lambda data: self._console_raw_callback("stderr", data),
                 ^^^^^^^^^^^^^^^^^^^^^^^^^^^^^^^^^^^^^^^^^^
  File "/opt/anaconda3/envs/myenv/lib/python3.11/site-packages/wandb/sdk/wandb_run.py", line 391, in wrapper
    return func(self, *args, **kwargs)
           ^^^^^^^^^^^^^^^^^^^^^^^^^^^
  File "/opt/anaconda3/envs/myenv/lib/python3.11/site-packages/wandb/sdk/wandb_run.py", line 449, in wrapper_fn
    return func(self, *args, **kwargs)
           ^^^^^^^^^^^^^^^^^^^^^^^^^^^
  File "/opt/anaconda3/envs/myenv/lib/python3.11/site-packages/wandb/sdk/wandb_run.py", line 1561, in _console_raw_callback
    self._backend.interface.publish_output_raw(name, data)
  File "/opt/anaconda3/envs/myenv/lib/python3.11/site-packages/wandb/sdk/interface/interface.py", line 772, in publish_output_raw
    self._publish_output_raw(o)
  File "/opt/anaconda3/envs/myenv/lib/python3.11/site-packages/wandb/sdk/interface/interface_shared.py", line 38, in _publish_output_raw
    self._publish(rec)
  File "/opt/anaconda3/envs/myenv/lib/python3.11/site-packages/wandb/sdk/interface/interface_sock.py", line 39, in _publish
    self._sock_client.send_record_publish(record)
  File "/opt/anaconda3/envs/myenv/lib/python3.11/site-packages/wandb/sdk/lib/sock_client.py", line 174, in send_record_publish
    self.send_server_request(server_req)
  File "/opt/anaconda3/envs/myenv/lib/python3.11/site-packages/wandb/sdk/lib/sock_client.py", line 154, in send_server_request
    self._send_message(msg)
  File "/opt/anaconda3/envs/myenv/lib/python3.11/site-packages/wandb/sdk/lib/sock_client.py", line 151, in _send_message
    self._sendall_with_error_handle(header + data)
  File "/opt/anaconda3/envs/myenv/lib/python3.11/site-packages/wandb/sdk/lib/sock_client.py", line 130, in _sendall_with_error_handle
    sent = self._sock.send(data)
           ^^^^^^^^^^^^^^^^^^^^^
BrokenPipeError: [Errno 32] Broken pipe
2025-07-16 11:32:13,165 ERROR   MainThread:59013 [redirect.py:_on_write():664] [no run ID] error in stderr callback
Traceback (most recent call last):
  File "/opt/anaconda3/envs/myenv/lib/python3.11/site-packages/wandb/sdk/lib/redirect.py", line 662, in _on_write
    cb(written_data)
  File "/opt/anaconda3/envs/myenv/lib/python3.11/site-packages/wandb/sdk/wandb_run.py", line 2380, in <lambda>
    lambda data: self._console_raw_callback("stderr", data),
                 ^^^^^^^^^^^^^^^^^^^^^^^^^^^^^^^^^^^^^^^^^^
  File "/opt/anaconda3/envs/myenv/lib/python3.11/site-packages/wandb/sdk/wandb_run.py", line 391, in wrapper
    return func(self, *args, **kwargs)
           ^^^^^^^^^^^^^^^^^^^^^^^^^^^
  File "/opt/anaconda3/envs/myenv/lib/python3.11/site-packages/wandb/sdk/wandb_run.py", line 449, in wrapper_fn
    return func(self, *args, **kwargs)
           ^^^^^^^^^^^^^^^^^^^^^^^^^^^
  File "/opt/anaconda3/envs/myenv/lib/python3.11/site-packages/wandb/sdk/wandb_run.py", line 1561, in _console_raw_callback
    self._backend.interface.publish_output_raw(name, data)
  File "/opt/anaconda3/envs/myenv/lib/python3.11/site-packages/wandb/sdk/interface/interface.py", line 772, in publish_output_raw
    self._publish_output_raw(o)
  File "/opt/anaconda3/envs/myenv/lib/python3.11/site-packages/wandb/sdk/interface/interface_shared.py", line 38, in _publish_output_raw
    self._publish(rec)
  File "/opt/anaconda3/envs/myenv/lib/python3.11/site-packages/wandb/sdk/interface/interface_sock.py", line 39, in _publish
    self._sock_client.send_record_publish(record)
  File "/opt/anaconda3/envs/myenv/lib/python3.11/site-packages/wandb/sdk/lib/sock_client.py", line 174, in send_record_publish
    self.send_server_request(server_req)
  File "/opt/anaconda3/envs/myenv/lib/python3.11/site-packages/wandb/sdk/lib/sock_client.py", line 154, in send_server_request
    self._send_message(msg)
  File "/opt/anaconda3/envs/myenv/lib/python3.11/site-packages/wandb/sdk/lib/sock_client.py", line 151, in _send_message
    self._sendall_with_error_handle(header + data)
  File "/opt/anaconda3/envs/myenv/lib/python3.11/site-packages/wandb/sdk/lib/sock_client.py", line 130, in _sendall_with_error_handle
    sent = self._sock.send(data)
           ^^^^^^^^^^^^^^^^^^^^^
BrokenPipeError: [Errno 32] Broken pipe
2025-07-16 11:32:13,166 ERROR   MainThread:59013 [redirect.py:_on_write():664] [no run ID] error in stderr callback
Traceback (most recent call last):
  File "/opt/anaconda3/envs/myenv/lib/python3.11/site-packages/wandb/sdk/lib/redirect.py", line 662, in _on_write
    cb(written_data)
  File "/opt/anaconda3/envs/myenv/lib/python3.11/site-packages/wandb/sdk/wandb_run.py", line 2380, in <lambda>
    lambda data: self._console_raw_callback("stderr", data),
                 ^^^^^^^^^^^^^^^^^^^^^^^^^^^^^^^^^^^^^^^^^^
  File "/opt/anaconda3/envs/myenv/lib/python3.11/site-packages/wandb/sdk/wandb_run.py", line 391, in wrapper
    return func(self, *args, **kwargs)
           ^^^^^^^^^^^^^^^^^^^^^^^^^^^
  File "/opt/anaconda3/envs/myenv/lib/python3.11/site-packages/wandb/sdk/wandb_run.py", line 449, in wrapper_fn
    return func(self, *args, **kwargs)
           ^^^^^^^^^^^^^^^^^^^^^^^^^^^
  File "/opt/anaconda3/envs/myenv/lib/python3.11/site-packages/wandb/sdk/wandb_run.py", line 1561, in _console_raw_callback
    self._backend.interface.publish_output_raw(name, data)
  File "/opt/anaconda3/envs/myenv/lib/python3.11/site-packages/wandb/sdk/interface/interface.py", line 772, in publish_output_raw
    self._publish_output_raw(o)
  File "/opt/anaconda3/envs/myenv/lib/python3.11/site-packages/wandb/sdk/interface/interface_shared.py", line 38, in _publish_output_raw
    self._publish(rec)
  File "/opt/anaconda3/envs/myenv/lib/python3.11/site-packages/wandb/sdk/interface/interface_sock.py", line 39, in _publish
    self._sock_client.send_record_publish(record)
  File "/opt/anaconda3/envs/myenv/lib/python3.11/site-packages/wandb/sdk/lib/sock_client.py", line 174, in send_record_publish
    self.send_server_request(server_req)
  File "/opt/anaconda3/envs/myenv/lib/python3.11/site-packages/wandb/sdk/lib/sock_client.py", line 154, in send_server_request
    self._send_message(msg)
  File "/opt/anaconda3/envs/myenv/lib/python3.11/site-packages/wandb/sdk/lib/sock_client.py", line 151, in _send_message
    self._sendall_with_error_handle(header + data)
  File "/opt/anaconda3/envs/myenv/lib/python3.11/site-packages/wandb/sdk/lib/sock_client.py", line 130, in _sendall_with_error_handle
    sent = self._sock.send(data)
           ^^^^^^^^^^^^^^^^^^^^^
BrokenPipeError: [Errno 32] Broken pipe
2025-07-16 11:32:13,166 ERROR   MainThread:59013 [redirect.py:_on_write():664] [no run ID] error in stderr callback
Traceback (most recent call last):
  File "/opt/anaconda3/envs/myenv/lib/python3.11/site-packages/wandb/sdk/lib/redirect.py", line 662, in _on_write
    cb(written_data)
  File "/opt/anaconda3/envs/myenv/lib/python3.11/site-packages/wandb/sdk/wandb_run.py", line 2380, in <lambda>
    lambda data: self._console_raw_callback("stderr", data),
                 ^^^^^^^^^^^^^^^^^^^^^^^^^^^^^^^^^^^^^^^^^^
  File "/opt/anaconda3/envs/myenv/lib/python3.11/site-packages/wandb/sdk/wandb_run.py", line 391, in wrapper
    return func(self, *args, **kwargs)
           ^^^^^^^^^^^^^^^^^^^^^^^^^^^
  File "/opt/anaconda3/envs/myenv/lib/python3.11/site-packages/wandb/sdk/wandb_run.py", line 449, in wrapper_fn
    return func(self, *args, **kwargs)
           ^^^^^^^^^^^^^^^^^^^^^^^^^^^
  File "/opt/anaconda3/envs/myenv/lib/python3.11/site-packages/wandb/sdk/wandb_run.py", line 1561, in _console_raw_callback
    self._backend.interface.publish_output_raw(name, data)
  File "/opt/anaconda3/envs/myenv/lib/python3.11/site-packages/wandb/sdk/interface/interface.py", line 772, in publish_output_raw
    self._publish_output_raw(o)
  File "/opt/anaconda3/envs/myenv/lib/python3.11/site-packages/wandb/sdk/interface/interface_shared.py", line 38, in _publish_output_raw
    self._publish(rec)
  File "/opt/anaconda3/envs/myenv/lib/python3.11/site-packages/wandb/sdk/interface/interface_sock.py", line 39, in _publish
    self._sock_client.send_record_publish(record)
  File "/opt/anaconda3/envs/myenv/lib/python3.11/site-packages/wandb/sdk/lib/sock_client.py", line 174, in send_record_publish
    self.send_server_request(server_req)
  File "/opt/anaconda3/envs/myenv/lib/python3.11/site-packages/wandb/sdk/lib/sock_client.py", line 154, in send_server_request
    self._send_message(msg)
  File "/opt/anaconda3/envs/myenv/lib/python3.11/site-packages/wandb/sdk/lib/sock_client.py", line 151, in _send_message
    self._sendall_with_error_handle(header + data)
  File "/opt/anaconda3/envs/myenv/lib/python3.11/site-packages/wandb/sdk/lib/sock_client.py", line 130, in _sendall_with_error_handle
    sent = self._sock.send(data)
           ^^^^^^^^^^^^^^^^^^^^^
BrokenPipeError: [Errno 32] Broken pipe
2025-07-16 11:32:13,169 ERROR   MainThread:59013 [redirect.py:_on_write():664] [no run ID] error in stderr callback
Traceback (most recent call last):
  File "/opt/anaconda3/envs/myenv/lib/python3.11/site-packages/wandb/sdk/lib/redirect.py", line 662, in _on_write
    cb(written_data)
  File "/opt/anaconda3/envs/myenv/lib/python3.11/site-packages/wandb/sdk/wandb_run.py", line 2380, in <lambda>
    lambda data: self._console_raw_callback("stderr", data),
                 ^^^^^^^^^^^^^^^^^^^^^^^^^^^^^^^^^^^^^^^^^^
  File "/opt/anaconda3/envs/myenv/lib/python3.11/site-packages/wandb/sdk/wandb_run.py", line 391, in wrapper
    return func(self, *args, **kwargs)
           ^^^^^^^^^^^^^^^^^^^^^^^^^^^
  File "/opt/anaconda3/envs/myenv/lib/python3.11/site-packages/wandb/sdk/wandb_run.py", line 449, in wrapper_fn
    return func(self, *args, **kwargs)
           ^^^^^^^^^^^^^^^^^^^^^^^^^^^
  File "/opt/anaconda3/envs/myenv/lib/python3.11/site-packages/wandb/sdk/wandb_run.py", line 1561, in _console_raw_callback
    self._backend.interface.publish_output_raw(name, data)
  File "/opt/anaconda3/envs/myenv/lib/python3.11/site-packages/wandb/sdk/interface/interface.py", line 772, in publish_output_raw
    self._publish_output_raw(o)
  File "/opt/anaconda3/envs/myenv/lib/python3.11/site-packages/wandb/sdk/interface/interface_shared.py", line 38, in _publish_output_raw
    self._publish(rec)
  File "/opt/anaconda3/envs/myenv/lib/python3.11/site-packages/wandb/sdk/interface/interface_sock.py", line 39, in _publish
    self._sock_client.send_record_publish(record)
  File "/opt/anaconda3/envs/myenv/lib/python3.11/site-packages/wandb/sdk/lib/sock_client.py", line 174, in send_record_publish
    self.send_server_request(server_req)
  File "/opt/anaconda3/envs/myenv/lib/python3.11/site-packages/wandb/sdk/lib/sock_client.py", line 154, in send_server_request
    self._send_message(msg)
  File "/opt/anaconda3/envs/myenv/lib/python3.11/site-packages/wandb/sdk/lib/sock_client.py", line 151, in _send_message
    self._sendall_with_error_handle(header + data)
  File "/opt/anaconda3/envs/myenv/lib/python3.11/site-packages/wandb/sdk/lib/sock_client.py", line 130, in _sendall_with_error_handle
    sent = self._sock.send(data)
           ^^^^^^^^^^^^^^^^^^^^^
BrokenPipeError: [Errno 32] Broken pipe
